Workbook

Sheet Matriz de Riesgos
A1: Matriz de Riesgos del Proyecto CuTuCo
A2: Nosotros identificamos, analizamos y controlamos los riesgos que podrían afectar a CuTuCo (Cultiva Tu Compra), un Marketplace SaaS B2B2C de comercio de proximidad para la Agricultura Familiar Campesina y pequeños productores locales de Chile. El proyecto lo realizamos entre dos personas en Duoc UC Plaza Norte (Ingeniería en Informática): Vicente Rivera (líder backend y Jefe de Proyecto, RUT 21.768.183-9) e Ignacio Fuenzalida (IT frontend, RUT 21.401.354-1). Trabajamos con un enfoque tradicional en 4 fases (planificación inicial, análisis y diseño, construcción, implementación y cierre) durante 13 semanas: inicio el 11 de septiembre de 2026 (semana 1), desarrollo hasta la semana 11 y preparación y entrega final en las semanas 12 y 13. Esta versión ya incorpora la actualización de alcance (tabla "Queda / No queda" de los 26 requerimientos): quedan 21, con varios recortados, y se descartan 5.
A3: Criterio de valoración de nosotros: Probabilidad e Impacto se puntúan de 1 a 5. El nivel se obtiene mediante Probabilidad × Impacto y nos permite priorizar las respuestas. Los puntajes son una valoración nuestra para planificar el trabajo, no una estadística externa; el detalle de cada puntaje está en la hoja "Instrucciones".
A5: ID | B5: Fase | C5: Riesgo identificado por nosotros | D5: Causa principal | E5: Consecuencia posible | F5: Prob. (1-5) | G5: Impacto (1-5) | H5: Nivel | I5: Prioridad | J5: Respuesta | K5: Acciones preventivas / controles | L5: Plan de contingencia | M5: Responsable principal | N5: Semana de control | O5: Estado | P5: Dependencias relacionadas | Q5: Observación / criterio del equipo
A6: 1 | B6: Planificación / Construcción | C6: Nosotros podríamos volver a ampliar el alcance con funcionalidades que ya recortamos o que no están validadas para el MVP. | D6: Con la actualización descartamos 5 de los 26 requerimientos (RF-008 historial de precios, RF-010 stock bajo, RF-013 múltiples administradores, RF-015 retención del carnet y RF-016 rate limiting) y recortamos varios más. Aun así el proyecto tiene muchas funciones y somos solo dos personas. | E6: Si reincorporamos funciones recortadas, gastaríamos semanas de desarrollo que necesitamos para pruebas, documentación y cierre. | F6: 4 | G6: 5 | H6: =F6*G6 -> 20 | I6: =IF(H6>=15,"Crítico",IF(H6>=10,"Alto",IF(H6>=5,"Medio","Bajo"))) -> Crítico | J6: Mitigar | K6: Nosotros usaremos la tabla "Queda / No queda" de la actualización como alcance oficial y como base de la Verificación de Alcances. Revisaremos el alcance cada semana, registraremos cada solicitud como cambio en la minuta de control y evaluaremos tiempo, riesgo, dependencias y valor antes de aceptarla. | L6: Nosotros congelaremos las funciones nuevas hasta cerrar los flujos críticos (login, compra, pago y entrega) y dejaremos lo solicitado anotado como mejora posterior, fuera del MVP académico. | M6: Vicente Rivera | N6: Semanas 1-13 | O6: Abierto | P6: Carta Gantt; Acta de Constitución; EDT; Minuta de Control; Verificación de Alcances | Q6: Por el tamaño del equipo es el riesgo que más vigilamos. Los recortes solo sirven si los respetamos hasta el cierre.
A7: 2 | B7: Análisis y Diseño / Construcción | C7: Nosotros podríamos tener problemas al migrar la persistencia de SQLite a PostgreSQL en Supabase y al adaptar el modelo de datos al nuevo alcance. | D7: El MVP usa SQLite local. El modelo nuevo agrega tablas (por ejemplo payouts) y deja de necesitar otras (historial de precios, alertas de stock y evidencias fotográficas). Todavía definimos si basta con ALTER TABLE o si conviene rediseñar el esquema completo. | E7: Podríamos perder datos, dejar relaciones o restricciones inconsistentes y retrasar los módulos que dependen de la base de datos. | F7: 3 | G7: 5 | H7: =F7*G7 -> 15 | I7: =IF(H7>=15,"Crítico",IF(H7>=10,"Alto",IF(H7>=5,"Medio","Bajo"))) -> Crítico | J7: Mitigar | K7: Nosotros modelaremos el ER en pgModeler, validaremos el esquema con DBeaver y decidiremos entre ALTER TABLE y rediseño completo antes de migrar. Versionaremos los scripts DDL, probaremos las restricciones UNIQUE y la integridad referencial, y migraremos por etapas verificando cada tabla. | L7: Nosotros mantendremos respaldos y la versión estable del modelo anterior. Si la migración falla, repetiremos la carga desde una estructura controlada con datos de prueba. | M7: Vicente Rivera | N7: Semanas 3-7 | O7: Abierto | P7: pgModeler; DBeaver; Supabase PostgreSQL; Scripts DDL; ERS | Q7: Es uno de los riesgos técnicos principales. Evaluamos antes el impacto de los recortes para no modelar tablas que ya no se usan.
A8: 3 | B8: Construcción / Implementación | C8: Nosotros podríamos cometer errores al integrar Transbank Webpay Plus en modo de prueba. | D8: Usamos Webpay Plus normal (no Webpay Diferido, que solo permite crédito, ni Webpay Mall). El flujo depende de create, redirección, token_ws y commit, y el retorno llega por GET, sin webhooks. | E8: El checkout podría quedar incompleto, duplicar órdenes o registrar estados de pago incorrectos. | F8: 3 | G8: 5 | H8: =F8*G8 -> 15 | I8: =IF(H8>=15,"Crítico",IF(H8>=10,"Alto",IF(H8>=5,"Medio","Bajo"))) -> Crítico | J8: Mitigar | K8: Nosotros probaremos por etapas el flujo create → redirección → token_ws → commit. Mantendremos buy_order y token_ws como valores UNIQUE en la tabla payments para lograr idempotencia, y guardaremos las credenciales de prueba en variables de entorno o Secret Manager, nunca en el repositorio. | L8: Nosotros usaremos mocks/stubs si Transbank bloquea las pruebas, dejaremos el pago en un estado controlado mientras corregimos y reintentaremos el commit manualmente. Cloud Tasks para reintentos queda proyectado solo para la Opción B. | M8: Vicente Rivera | N8: Semanas 7-10 | O8: Abierto | P8: Transbank Webpay Plus; Secret Manager / variables de entorno; Supabase; Tabla payments | Q8: La idempotencia es el control central. Si el pago falla, falla todo el flujo de compra.
A9: 4 | B9: Construcción / Implementación | C9: Nosotros podríamos calcular mal la comisión, los payouts o los reembolsos, o exponer los datos bancarios de los productores. | D9: Cambiamos el flujo de dinero: CuTuCo retiene el 100% de la venta y, después de entregar el pedido, simula un payout manual al productor. Esto exige una tabla payouts y pedir banco, número y tipo de cuenta, que debemos cifrar. La liquidación descuenta un fee base de 5% y la tarifa fija de delivery de 3.500 CLP. | E9: Podríamos liquidar montos incorrectos, no poder devolver dinero al cliente o filtrar datos financieros sensibles. | F9: 3 | G9: 4 | H9: =F9*G9 -> 12 | I9: =IF(H9>=15,"Crítico",IF(H9>=10,"Alto",IF(H9>=5,"Medio","Bajo"))) -> Alto | J9: Mitigar | K9: Nosotros definiremos la fórmula de liquidación (venta menos fee de 5% menos tarifa fija de 3.500 CLP) con pruebas unitarias y guardaremos el detalle de cada cálculo. Cifraremos los datos bancarios, los protegeremos con RLS y policies de Supabase y limitaremos su lectura al Administrador. | L9: Nosotros bloquearemos el payout afectado, recalcularemos el monto y registraremos el ajuste. Si hubo exposición de datos, cambiaremos las claves de cifrado y revisaremos los accesos. | M9: Vicente Rivera | N9: Semanas 7-10 | O9: Abierto | P9: Tabla payouts; Webpay Plus; Supabase (RLS); Dashboard Administrativo; RF-014 | Q9: Sobre la legalidad, revisamos la Ley Fintech y por ahora la descartamos porque apunta a activos financieros y criptoactivos. Si cambia la forma de retener el dinero, la volveremos a revisar. El payout es una simulación manual en el MVP.
A10: 5 | B10: Construcción | C10: Nosotros podríamos generar inconsistencias de stock por concurrencia al comprar. | D10: Varios clientes podrían comprar el mismo producto a la vez mientras el productor modifica el stock. Cada productor tiene su propio catálogo y el stock cambia por temporada. | E10: Podríamos aceptar compras sobre stock inexistente o mostrar cantidades erróneas en el catálogo. | F10: 3 | G10: 3 | H10: =F10*G10 -> 9 | I10: =IF(H10>=15,"Crítico",IF(H10>=10,"Alto",IF(H10>=5,"Medio","Bajo"))) -> Medio | J10: Mitigar | K10: Nosotros validaremos el stock dentro de una transacción de base de datos (SELECT FOR UPDATE) antes de crear el pago y probaremos compras simultáneas del mismo producto. El umbral de stock bajo quedó fuera del alcance, así que no dependemos de alertas. | L10: Nosotros rechazaremos la operación cuando el stock no alcance, mostraremos el stock actualizado al cliente y corregiremos a mano las órdenes afectadas. | M10: Vicente Rivera | N10: Semanas 6-9 | O10: Abierto | P10: PostgreSQL; Orders; Order Items; API REST | Q10: Sin alertas automáticas, el productor revisa su stock a mano. Lo dejamos anotado como limitación del MVP.
A11: 6 | B11: Construcción / Implementación | C11: Nosotros podríamos tener errores de autenticación, permisos o políticas de acceso (RLS) con Supabase. | D11: Login y refresh van directo con Supabase GoTrue, el bloqueo de cuenta tras 5 intentos fallidos lo hace FastAPI y varias consultas simples van directo a PostgREST. Hay tres perfiles (Cliente, Vendedor y Administrador) y debemos verificar de nuevo las RLS y policies que ya creamos. | E11: Un usuario podría ver o modificar datos de otro rol, o quedar bloqueado sin motivo válido. | F11: 3 | G11: 5 | H11: =F11*G11 -> 15 | I11: =IF(H11>=15,"Crítico",IF(H11>=10,"Alto",IF(H11>=5,"Medio","Bajo"))) -> Crítico | J11: Mitigar | K11: Nosotros probaremos cada RLS y policy con un usuario por rol. Dejaremos que GoTrue aplique su rate limiting nativo (respuesta 429) y que FastAPI solo actualice intentos_login_fallidos y bloqueado_hasta. Impediremos el auto-registro como Administrador y probaremos la expiración de JWT y del refresh. | L11: Nosotros revocaremos las sesiones afectadas, corregiremos las policies y repetiremos las pruebas de seguridad antes de cerrar el módulo. | M11: Vicente Rivera | N11: Semanas 4-8 | O11: Abierto | P11: Supabase GoTrue; PostgREST; RLS y policies; FastAPI; Roles | Q11: La autenticación atraviesa todos los módulos. Como el login ya no pasa por FastAPI, la seguridad depende más de la configuración de Supabase y la revisamos con más cuidado.
A12: 7 | B12: Construcción | C12: Nosotros podríamos retrasarnos al construir backend, frontend e integración al mismo tiempo. | D12: Somos dos personas con especialidad por capa: Vicente en backend, pagos y base de datos, e Ignacio en Vue.js, paneles y dashboard. | E12: Podríamos acumular trabajo pendiente y quedarnos sin tiempo de integración y pruebas. Si uno de los dos se bloquea o se enferma, un bloque crítico queda sin respaldo. | F12: 4 | G12: 4 | H12: =F12*G12 -> 16 | I12: =IF(H12>=15,"Crítico",IF(H12>=10,"Alto",IF(H12>=5,"Medio","Bajo"))) -> Crítico | J12: Mitigar | K12: Nosotros separaremos las responsabilidades por especialidad según la matriz RACI, coordinaremos las integraciones en la revisión semanal y priorizaremos los flujos críticos. Nos revisaremos el trabajo entre ambos antes de cerrar cada bloque para que los dos conozcamos todo el sistema. | L12: Nosotros reduciremos el trabajo en paralelo, congelaremos las mejoras secundarias y concentraremos ambos esfuerzos en login, catálogo, checkout, pago y entrega. | M12: Vicente Rivera e Ignacio Fuenzalida | N12: Semanas 4-11 | O12: Abierto | P12: Carta Gantt; RACI; Minuta de Control de Programación | Q12: Planificamos de forma conservadora porque somos dos. El recorte de funciones ayuda a bajar esta carga.
A13: 8 | B13: Análisis y Diseño / Construcción | C13: Nosotros podríamos generar inconsistencias entre el frontend de Vue.js, PostgREST y FastAPI, o cambiar la arquitectura demasiado tarde. | D13: Migramos desde una solución monolítica en Ionic/Angular hacia Vue.js con Vite. La actualización repartió el trabajo entre PostgREST (consultas simples), GoTrue (autenticación) y FastAPI (lógica de negocio como pagos), y aún evaluamos qué endpoints van por cada vía. | E13: Podrían aparecer errores de formato, estados o validaciones duplicadas, y tendríamos que rehacer código y documentos. | F13: 3 | G13: 3 | H13: =F13*G13 -> 9 | I13: =IF(H13>=15,"Crítico",IF(H13>=10,"Alto",IF(H13>=5,"Medio","Bajo"))) -> Medio | J13: Mitigar | K13: Nosotros definiremos qué se consulta por PostgREST y qué por FastAPI y fijaremos los contratos de API. Validaremos principalmente en el front con Vuelidate y de forma mínima en el backend con Pydantic y las restricciones de la base de datos. Registraremos cada decisión en la minuta y actualizaremos los documentos afectados. | L13: Nosotros aislaremos el endpoint afectado, corregiremos el contrato y repetiremos las pruebas E2E de ese flujo. Elegiremos la alternativa compatible con el alcance validado y dejaremos la decisión escrita. | M13: Ignacio Fuenzalida | N13: Semanas 3-10 | O13: Abierto | P13: Vue.js + Vite; PostgREST; FastAPI; Pydantic; Vuelidate; Minuta de Control | Q13: Dejamos la validación principal en el front y una mínima en el backend para no duplicar lógica en un MVP pequeño. La base de datos queda como última barrera.
A14: 9 | B14: Construcción / Implementación | C14: Nosotros podríamos quedar bloqueados por fallas o límites de servicios externos. | D14: El proyecto depende de Supabase (PostgreSQL y Auth), Vercel, GCP Cloud Run, Transbank Webpay Plus Test y Resend para los correos (SMTP de Auth configurado en Supabase y API de Resend para las notificaciones de negocio). | E14: Podríamos detener tareas aunque nuestro código esté listo, o dejar de enviar correos de recuperación de contraseña y avisos de pago retenido. | F14: 3 | G14: 4 | H14: =F14*G14 -> 12 | I14: =IF(H14>=15,"Crítico",IF(H14>=10,"Alto",IF(H14>=5,"Medio","Bajo"))) -> Alto | J14: Mitigar | K14: Nosotros mantendremos mocks/stubs para las pruebas, usaremos variables de entorno por ambiente y avanzaremos primero en las tareas que no dependan de un servicio externo. | L14: Nosotros seguiremos con pruebas locales, documentación y módulos desacoplados hasta que el servicio vuelva, y repetiremos las validaciones reales antes de dar por terminado el flujo afectado. | M14: Vicente Rivera e Ignacio Fuenzalida | N14: Semanas 4-11 | O14: Abierto | P14: Supabase; Vercel; GCP Cloud Run; Transbank; Resend | Q14: El informe reconoce estas dependencias en la factibilidad. Los correos de Auth quedan en Supabase y los de negocio (pago retenido, aprobación de productor, payout y reembolso) salen por la API de Resend.
A15: 10 | B15: Implementación / Cierre | C15: Nosotros podríamos quedarnos sin los créditos gratuitos de GCP antes de terminar las pruebas y la entrega. | D15: La Opción A usa Cloud Run en us-central1 con US$300 de créditos que duran hasta el 29 de noviembre, y la entrega final es en la semana 13 (10 de diciembre). | E15: El backend podría dejar de estar disponible durante las pruebas finales o la presentación, o generar un cobro que no previmos. | F15: 4 | G15: 3 | H15: =F15*G15 -> 12 | I15: =IF(H15>=15,"Crítico",IF(H15>=10,"Alto",IF(H15>=5,"Medio","Bajo"))) -> Alto | J15: Mitigar | K15: Nosotros mantendremos la configuración mínima (512Mi, mínimo 0 y máximo 5 instancias), revisaremos el consumo en billing cada semana y evitaremos desplegar recursos que no necesitemos. | L15: Nosotros migraremos el backend a otra cuenta de GCP al terminar el desarrollo, como ya anotamos en la arquitectura, y dejaremos listos el Dockerfile y las variables de entorno para redesplegar rápido. | M15: Vicente Rivera | N15: Semanas 9-12 | O15: Abierto | P15: GCP Cloud Run; Docker; GitHub Actions; Secret Manager | Q15: Es una fecha conocida, por eso la probabilidad es alta. No usamos la Opción B (dos regiones) porque cuesta cerca de 40% más y no es parte del MVP.
A16: 11 | B16: Construcción / Implementación | C16: Nosotros podríamos aprobar productores sin una verificación suficiente o saturar al único Administrador con tareas manuales. | D16: Con la actualización ya no pedimos el carnet (RF-015 quedó fuera) y pasamos a una revisión manual: el Administrador hace un background check del productor, aprueba cuentas y pagos y gestiona sanciones (lista de palabras prohibidas con LIKE, conteo de amonestaciones y botón de baneo permanente). Por ahora hay un solo Administrador. | E16: Podríamos dejar pasar cuentas fraudulentas, aplicar sanciones con criterios distintos o demorar la aprobación de productores y payouts. | F16: 3 | G16: 4 | H16: =F16*G16 -> 12 | I16: =IF(H16>=15,"Crítico",IF(H16>=10,"Alto",IF(H16>=5,"Medio","Bajo"))) -> Alto | J16: Mitigar | K16: Nosotros definiremos un checklist para aprobar productores (datos de la tienda, correo y verificación manual), registraremos cada aprobación, rechazo y sanción con fecha y motivo, y probaremos la lista de palabras prohibidas con casos de falsos positivos antes de usarla. Mantendremos visibles los pendientes del Administrador en el dashboard. | L16: Nosotros pausaremos las cuentas dudosas hasta completar la revisión, revertiremos a mano las sanciones aplicadas por error y atenderemos primero las aprobaciones y pagos pendientes. | M16: Ignacio Fuenzalida | N16: Semanas 7-11 | O16: Abierto | P16: Panel de Administración; Dashboard; RF-004; RF-021; RF-026 | Q16: Quitamos la automatización (score para suspender, validación del carnet) para bajar la complejidad. A cambio, la revisión humana pasa a ser un control que tenemos que cuidar.
A17: 12 | B17: Construcción / Implementación | C17: Nosotros podríamos tener fallas en el código de verificación de entrega que reemplazó a las fotos. | D17: La actualización dejó fuera la evidencia fotográfica obligatoria y cambió la confirmación a un código de verificación al momento de la entrega. El seguimiento queda solo con los estados Preparación → En Tránsito → Entregado, sin GPS ni mapa en tiempo real. | E17: Podríamos tener pedidos que no se cierran, pagos retenidos sin liberar o disputas con menos respaldo, porque ya no hay fotos de la entrega. | F17: 3 | G17: 3 | H17: =F17*G17 -> 9 | I17: =IF(H17>=15,"Crítico",IF(H17>=10,"Alto",IF(H17>=5,"Medio","Bajo"))) -> Medio | J17: Mitigar | K17: Nosotros generaremos un código único por pedido, lo validaremos en el backend antes de marcar el pedido como Entregado, limitaremos los intentos y probaremos los casos de código incorrecto, repetido o perdido. Registraremos cada cambio de estado con fecha y usuario. | L17: Nosotros dejaremos que el Administrador revise el pedido y resuelva el caso a mano (marcar como entregado, rechazar o reembolsar) apoyándose en el registro de estados. | M17: Vicente Rivera e Ignacio Fuenzalida | N17: Semanas 6-10 | O17: Abierto | P17: delivery_tracking; Orders; RF-007; RF-025; Vue.js | Q17: Sin fotos perdemos respaldo visual ante una disputa. Lo aceptamos para reducir complejidad y lo dejamos documentado.
... A20: 15 | B20: Implementación / Cierre | C20: Nosotros podríamos dejar incompleta o desactualizada la documentación final. | D20: Entregamos muchos documentos en 4 fases (ERS, modelos de datos, arquitectura, mockups, plan de calidad y costos, plan de pruebas final, plan de implantación, soporte y mantenimiento, y manuales), y la actualización de alcance cambia varios que ya estaban escritos. | E20: Podríamos tener un producto funcionando pero una entrega académica incompleta, contradictoria o difícil de mantener. | F20: 3 | G20: 4 | H20: =F20*G20 -> 12 | I20: =IF(H20>=15,"Crítico",IF(H20>=10,"Alto",IF(H20>=5,"Medio","Bajo"))) -> Alto | J20: Mitigar | K20: Nosotros actualizaremos la documentación al ritmo del desarrollo, corregiremos primero los documentos afectados por la actualización (ERS, plan de pruebas, EDT y modelo de datos) y reservaremos la semana 12 para los manuales y el plan de soporte. | L20: Nosotros haremos una lista de documentos pendientes, cerraremos primero los obligatorios y revisaremos que cada uno coincida con la versión realmente implementada. | M20: Ignacio Fuenzalida | N20: Semanas 10-13 | O20: Abierto | P20: Manual de Usuario; Manual de Administrador; Plan de Implantación, Soporte y Mantenimiento; Reporte de Estatus Final | Q20: La documentación es compartida, aunque Ignacio lidera la compilación de los manuales.
A22: Resumen de nosotros: priorizamos los riesgos con mayor combinación de probabilidad e impacto. Los más urgentes hoy son el control del alcance (1), el cierre con errores críticos pendientes (14), la migración de datos (2), la integración con Webpay (3), la seguridad de accesos con Supabase (6) y el retraso por ser solo dos personas (7). Revisaremos la matriz semanalmente y registraremos cambios, nuevos riesgos o cierres en la minuta de control del proyecto. Cuando una actualización de alcance cambie un riesgo, ajustaremos probabilidad e impacto y lo dejaremos anotado.
A24: Cantidad de riesgos | E24: =COUNTA(A6:A20) -> 15 | I24: Riesgos críticos / altos | M24: =COUNTIF(I6:I20,"Crítico")+COUNTIF(I6:I20,"Alto") -> 11

Sheet Gráfico Matriz
A1: Gráfico de la Matriz de Riesgos CuTuCo (Probabilidad × Impacto)
A2: Nosotros ubicamos cada riesgo (por su ID) según la Probabilidad y el Impacto que valoramos en la hoja "Matriz de Riesgos". El gráfico se actualiza solo si cambiamos esos puntajes.
C4: 1 Muy bajo | D4: 2 Bajo | E4: 3 Medio | F4: 4 Alto | G4: 5 Muy alto
A5: PROBABILIDAD | B5: 5 Muy alta | C5: =MID(IF(AND('Matriz de Riesgos'!$F$6=5,'Matriz de Riesgos'!$G$6=1),", "&'Matriz de Riesgos'!$A$6,"")&IF(AND('Matriz de Riesgos'!$F$7=5,'Matriz de Riesgos'!$G$7=1),", "&'Matriz de Riesgos'!$A$7,"")&IF(AND('Matriz de Riesgos'!$F$8=5,'Matriz de Riesgos'!$G$8=1),", "&'Matriz de Riesgos'!$A$8,"")&IF(AND('Matriz de Riesgos'!$F$9=5,'Matriz de Riesgos'!$G$9=1),", "&'Matriz de Riesgos'!$A$9,"")&IF(AND('Matriz de Riesgos'!$F$10=5,'Matriz de Riesgos'!$G$10=1),", "&'Matriz de Riesgos'!$A$10,"")&IF(AND('Matriz de Riesgos'!$F$11=5,'Matriz de Riesgos'!$G$11=1),", "&'Matriz de Riesgos'!$A$11,"")&IF(AND('Matriz de Riesgos'!$F$12=5,'Matriz de Riesgos'!$G$12=1),", "&'Matriz de Riesgos'!$A$12,"")&IF(AND('Matriz de Riesgos'!$F$13=5,'Matriz de Riesgos'!$G$13=1),", "&'Matriz de Riesgos'!$A$13,"")&IF(AND('Matriz de Riesgos'!$F$14=5,'Matriz de Riesgos'!$G$14=1),", "&'Matriz de Riesgos'!$A$14,"")&IF(AND('Matriz de Riesgos'!$F$15=5,'Matriz de Riesgos'!$G$15=1),", "&'Matriz de Riesgos'!$A$15,"")&IF(AND('Matriz de Riesgos'!$F$16=5,'Matriz de Riesgos'!$G$16=1),", "&'Matriz de Riesgos'!$A$16,"")&IF(AND('Matriz de Riesgos'!$F$17=5,'Matriz de Riesgos'!$G$17=1),", "&'Matriz de Riesgos'!$A$17,"")&IF(AND('Matriz de Riesgos'!$F$18=5,'Matriz de Riesgos'!$G$18=1),", "&'Matriz de Riesgos'!$A$18,"")&IF(AND('Matriz de Riesgos'!$F$19=5,'Matriz de Riesgos'!$G$19=1),", "&'Matriz de Riesgos'!$A$19,"")&IF(AND('Matriz de Riesgos'!$F$20=5,'Matriz de Riesgos'!$G$20=1),", "&'Matriz de Riesgos'!$A$20,""),3,100) | D5: =MID(IF(AND('Matriz de Riesgos'!$F$6=5,'Matriz de Riesgos'!$G$6=2),", "&'Matriz de Riesgos'!$A$6,"")&IF(AND('Matriz de Riesgos'!$F$7=5,'Matriz de Riesgos'!$G$7=2),", "&'Matriz de Riesgos'!$A$7,"")&IF(AND('Matriz de Riesgos'!$F$8=5,'Matriz de Riesgos'!$G$8=2),", "&'Matriz de Riesgos'!$A$8,"")&IF(AND('Matriz de Riesgos'!$F$9=5,'Matriz de Riesgos'!$G$9=2),", "&'Matriz de Riesgos'!$A$9,"")&IF(AND('Matriz de Riesgos'!$F$10=5,'Matriz de Riesgos'!$G$10=2),", "&'Matriz de Riesgos'!$A$10,"")&IF(AND('Matriz de Riesgos'!$F$11=5,'Matriz de Riesgos'!$G$11=2),", "&'Matriz de Riesgos'!$A$11,"")&IF(AND('Matriz de Riesgos'!$F$12=5,'Matriz de Riesgos'!$G$12=2),", "&'Matriz de Riesgos'!$A$12,"")&IF(AND('Matriz de Riesgos'!$F$13=5,'Matriz de Riesgos'!$G$13=2),", "&'Matriz de Riesgos'!$A$13,"")&IF(AND('Matriz de Riesgos'!$F$14=5,'Matriz de Riesgos'!$G$14=2),", "&'Matriz de Riesgos'!$A$14,"")&IF(AND('Matriz de Riesgos'!$F$15=5,'Matriz de Riesgos'!$G$15=2),", "&'Matriz de Riesgos'!$A$15,"")&IF(AND('Matriz de Riesgos'!$F$16=5,'Matriz de Riesgos'!$G$16=2),", "&'Matriz de Riesgos'!$A$16,"")&IF(AND('Matriz de Riesgos'!$F$17=5,'Matriz de Riesgos'!$G$17=2),", "&'Matriz de Riesgos'!$A$17,"")&IF(AND('Matriz de Riesgos'!$F$18=5,'Matriz de Riesgos'!$G$18=2),", "&'Matriz de Riesgos'!$A$18,"")&IF(AND('Matriz de Riesgos'!$F$19=5,'Matriz de Riesgos'!$G$19=2),", "&'Matriz de Riesgos'!$A$19,"")&IF(AND('Matriz de Riesgos'!$F$20=5,'Matriz de Riesgos'!$G$20=2),", "&'Matriz de Riesgos'!$A$20,""),3,100) | E5: =MID(IF(AND('Matriz de Riesgos'!$F$6=5,'Matriz de Riesgos'!$G$6=3),", "&'Matriz de Riesgos'!$A$6,"")&IF(AND('Matriz de Riesgos'!$F$7=5,'Matriz de Riesgos'!$G$7=3),", "&'Matriz de Riesgos'!$A$7,"")&IF(AND('Matriz de Riesgos'!$F$8=5,'Matriz de Riesgos'!$G$8=3),", "&'Matriz de Riesgos'!$A$8,"")&IF(AND('Matriz de Riesgos'!$F$9=5,'Matriz de Riesgos'!$G$9=3),", "&'Matriz de Riesgos'!$A$9,"")&IF(AND('Matriz de Riesgos'!$F$10=5,'Matriz de Riesgos'!$G$10=3),", "&'Matriz de Riesgos'!$A$10,"")&IF(AND('Matriz de Riesgos'!$F$11=5,'Matriz de Riesgos'!$G$11=3),", "&'Matriz de Riesgos'!$A$11,"")&IF(AND('Matriz de Riesgos'!$F$12=5,'Matriz de Riesgos'!$G$12=3),", "&'Matriz de Riesgos'!$A$12,"")&IF(AND('Matriz de Riesgos'!$F$13=5,'Matriz de Riesgos'!$G$13=3),", "&'Matriz de Riesgos'!$A$13,"")&IF(AND('Matriz de Riesgos'!$F$14=5,'Matriz de Riesgos'!$G$14=3),", "&'Matriz de Riesgos'!$A$14,"")&IF(AND('Matriz de Riesgos'!$F$15=5,'Matriz de Riesgos'!$G$15=3),", "&'Matriz de Riesgos'!$A$15,"")&IF(AND('Matriz de Riesgos'!$F$16=5,'Matriz de Riesgos'!$G$16=3),", "&'Matriz de Riesgos'!$A$16,"")&IF(AND('Matriz de Riesgos'!$F$17=5,'Matriz de Riesgos'!$G$17=3),", "&'Matriz de Riesgos'!$A$17,"")&IF(AND('Matriz de Riesgos'!$F$18=5,'Matriz de Riesgos'!$G$18=3),", "&'Matriz de Riesgos'!$A$18,"")&IF(AND('Matriz de Riesgos'!$F$19=5,'Matriz de Riesgos'!$G$19=3),", "&'Matriz de Riesgos'!$A$19,"")&IF(AND('Matriz de Riesgos'!$F$20=5,'Matriz de Riesgos'!$G$20=3),", "&'Matriz de Riesgos'!$A$20,""),3,100) | F5: =MID(IF(AND('Matriz de Riesgos'!$F$6=5,'Matriz de Riesgos'!$G$6=4),", "&'Matriz de Riesgos'!$A$6,"")&IF(AND('Matriz de Riesgos'!$F$7=5,'Matriz de Riesgos'!$G$7=4),", "&'Matriz de Riesgos'!$A$7,"")&IF(AND('Matriz de Riesgos'!$F$8=5,'Matriz de Riesgos'!$G$8=4),", "&'Matriz de Riesgos'!$A$8,"")&IF(AND('Matriz de Riesgos'!$F$9=5,'Matriz de Riesgos'!$G$9=4),", "&'Matriz de Riesgos'!$A$9,"")&IF(AND('Matriz de Riesgos'!$F$10=5,'Matriz de Riesgos'!$G$10=4),", "&'Matriz de Riesgos'!$A$10,"")&IF(AND('Matriz de Riesgos'!$F$11=5,'Matriz de Riesgos'!$G$11=4),", "&'Matriz de Riesgos'!$A$11,"")&IF(AND('Matriz de Riesgos'!$F$12=5,'Matriz de Riesgos'!$G$12=4),", "&'Matriz de Riesgos'!$A$12,"")&IF(AND('Matriz de Riesgos'!$F$13=5,'Matriz de Riesgos'!$G$13=4),", "&'Matriz de Riesgos'!$A$13,"")&IF(AND('Matriz de Riesgos'!$F$14=5,'Matriz de Riesgos'!$G$14=4),", "&'Matriz de Riesgos'!$A$14,"")&IF(AND('Matriz de Riesgos'!$F$15=5,'Matriz de Riesgos'!$G$15=4),", "&'Matriz de Riesgos'!$A$15,"")&IF(AND('Matriz de Riesgos'!$F$16=5,'Matriz de Riesgos'!$G$16=4),", "&'Matriz de Riesgos'!$A$16,"")&IF(AND('Matriz de Riesgos'!$F$17=5,'Matriz de Riesgos'!$G$17=4),", "&'Matriz de Riesgos'!$A$17,"")&IF(AND('Matriz de Riesgos'!$F$18=5,'Matriz de Riesgos'!$G$18=4),", "&'Matriz de Riesgos'!$A$18,"")&IF(AND('Matriz de Riesgos'!$F$19=5,'Matriz de Riesgos'!$G$19=4),", "&'Matriz de Riesgos'!$A$19,"")&IF(AND('Matriz de Riesgos'!$F$20=5,'Matriz de Riesgos'!$G$20=4),", "&'Matriz de Riesgos'!$A$20,""),3,100) | G5: =MID(IF(AND('Matriz de Riesgos'!$F$6=5,'Matriz de Riesgos'!$G$6=5),", "&'Matriz de Riesgos'!$A$6,"")&IF(AND('Matriz de Riesgos'!$F$7=5,'Matriz de Riesgos'!$G$7=5),", "&'Matriz de Riesgos'!$A$7,"")&IF(AND('Matriz de Riesgos'!$F$8=5,'Matriz de Riesgos'!$G$8=5),", "&'Matriz de Riesgos'!$A$8,"")&IF(AND('Matriz de Riesgos'!$F$9=5,'Matriz de Riesgos'!$G$9=5),", "&'Matriz de Riesgos'!$A$9,"")&IF(AND('Matriz de Riesgos'!$F$10=5,'Matriz de Riesgos'!$G$10=5),", "&'Matriz de Riesgos'!$A$10,"")&IF(AND('Matriz de Riesgos'!$F$11=5,'Matriz de Riesgos'!$G$11=5),", "&'Matriz de Riesgos'!$A$11,"")&IF(AND('Matriz de Riesgos'!$F$12=5,'Matriz de Riesgos'!$G$12=5),", "&'Matriz de Riesgos'!$A$12,"")&IF(AND('Matriz de Riesgos'!$F$13=5,'Matriz de Riesgos'!$G$13=5),", "&'Matriz de Riesgos'!$A$13,"")&IF(AND('Matriz de Riesgos'!$F$14=5,'Matriz de Riesgos'!$G$14=5),", "&'Matriz de Riesgos'!$A$14,"")&IF(AND('Matriz de Riesgos'!$F$15=5,'Matriz de Riesgos'!$G$15=5),", "&'Matriz de Riesgos'!$A$15,"")&IF(AND('Matriz de Riesgos'!$F$16=5,'Matriz de Riesgos'!$G$16=5),", "&'Matriz de Riesgos'!$A$16,"")&IF(AND('Matriz de Riesgos'!$F$17=5,'Matriz de Riesgos'!$G$17=5),", "&'Matriz de Riesgos'!$A$17,"")&IF(AND('Matriz de Riesgos'!$F$18=5,'Matriz de Riesgos'!$G$18=5),", "&'Matriz de Riesgos'!$A$18,"")&IF(AND('Matriz de Riesgos'!$F$19=5,'Matriz de Riesgos'!$G$19=5),", "&'Matriz de Riesgos'!$A$19,"")&IF(AND('Matriz de Riesgos'!$F$20=5,'Matriz de Riesgos'!$G$20=5),", "&'Matriz de Riesgos'!$A$20,""),3,100)
B6: 4 Alta | C6: =MID(IF(AND('Matriz de Riesgos'!$F$6=4,'Matriz de Riesgos'!$G$6=1),", "&'Matriz de Riesgos'!$A$6,"")&IF(AND('Matriz de Riesgos'!$F$7=4,'Matriz de Riesgos'!$G$7=1),", "&'Matriz de Riesgos'!$A$7,"")&IF(AND('Matriz de Riesgos'!$F$8=4,'Matriz de Riesgos'!$G$8=1),", "&'Matriz de Riesgos'!$A$8,"")&IF(AND('Matriz de Riesgos'!$F$9=4,'Matriz de Riesgos'!$G$9=1),", "&'Matriz de Riesgos'!$A$9,"")&IF(AND('Matriz de Riesgos'!$F$10=4,'Matriz de Riesgos'!$G$10=1),", "&'Matriz de Riesgos'!$A$10,"")&IF(AND('Matriz de Riesgos'!$F$11=4,'Matriz de Riesgos'!$G$11=1),", "&'Matriz de Riesgos'!$A$11,"")&IF(AND('Matriz de Riesgos'!$F$12=4,'Matriz de Riesgos'!$G$12=1),", "&'Matriz de Riesgos'!$A$12,"")&IF(AND('Matriz de Riesgos'!$F$13=4,'Matriz de Riesgos'!$G$13=1),", "&'Matriz de Riesgos'!$A$13,"")&IF(AND('Matriz de Riesgos'!$F$14=4,'Matriz de Riesgos'!$G$14=1),", "&'Matriz de Riesgos'!$A$14,"")&IF(AND('Matriz de Riesgos'!$F$15=4,'Matriz de Riesgos'!$G$15=1),", "&'Matriz de Riesgos'!$A$15,"")&IF(AND('Matriz de Riesgos'!$F$16=4,'Matriz de Riesgos'!$G$16=1),", "&'Matriz de Riesgos'!$A$16,"")&IF(AND('Matriz de Riesgos'!$F$17=4,'Matriz de Riesgos'!$G$17=1),", "&'Matriz de Riesgos'!$A$17,"")&IF(AND('Matriz de Riesgos'!$F$18=4,'Matriz de Riesgos'!$G$18=1),", "&'Matriz de Riesgos'!$A$18,"")&IF(AND('Matriz de Riesgos'!$F$19=4,'Matriz de Riesgos'!$G$19=1),", "&'Matriz de Riesgos'!$A$19,"")&IF(AND('Matriz de Riesgos'!$F$20=4,'Matriz de Riesgos'!$G$20=1),", "&'Matriz de Riesgos'!$A$20,""),3,100) | D6: =MID(IF(AND('Matriz de Riesgos'!$F$6=4,'Matriz de Riesgos'!$G$6=2),", "&'Matriz de Riesgos'!$A$6,"")&IF(AND('Matriz de Riesgos'!$F$7=4,'Matriz de Riesgos'!$G$7=2),", "&'Matriz de Riesgos'!$A$7,"")&IF(AND('Matriz de Riesgos'!$F$8=4,'Matriz de Riesgos'!$G$8=2),", "&'Matriz de Riesgos'!$A$8,"")&IF(AND('Matriz de Riesgos'!$F$9=4,'Matriz de Riesgos'!$G$9=2),", "&'Matriz de Riesgos'!$A$9,"")&IF(AND('Matriz de Riesgos'!$F$10=4,'Matriz de Riesgos'!$G$10=2),", "&'Matriz de Riesgos'!$A$10,"")&IF(AND('Matriz de Riesgos'!$F$11=4,'Matriz de Riesgos'!$G$11=2),", "&'Matriz de Riesgos'!$A$11,"")&IF(AND('Matriz de Riesgos'!$F$12=4,'Matriz de Riesgos'!$G$12=2),", "&'Matriz de Riesgos'!$A$12,"")&IF(AND('Matriz de Riesgos'!$F$13=4,'Matriz de Riesgos'!$G$13=2),", "&'Matriz de Riesgos'!$A$13,"")&IF(AND('Matriz de Riesgos'!$F$14=4,'Matriz de Riesgos'!$G$14=2),", "&'Matriz de Riesgos'!$A$14,"")&IF(AND('Matriz de Riesgos'!$F$15=4,'Matriz de Riesgos'!$G$15=2),", "&'Matriz de Riesgos'!$A$15,"")&IF(AND('Matriz de Riesgos'!$F$16=4,'Matriz de Riesgos'!$G$16=2),", "&'Matriz de Riesgos'!$A$16,"")&IF(AND('Matriz de Riesgos'!$F$17=4,'Matriz de Riesgos'!$G$17=2),", "&'Matriz de Riesgos'!$A$17,"")&IF(AND('Matriz de Riesgos'!$F$18=4,'Matriz de Riesgos'!$G$18=2),", "&'Matriz de Riesgos'!$A$18,"")&IF(AND('Matriz de Riesgos'!$F$19=4,'Matriz de Riesgos'!$G$19=2),", "&'Matriz de Riesgos'!$A$19,"")&IF(AND('Matriz de Riesgos'!$F$20=4,'Matriz de Riesgos'!$G$20=2),", "&'Matriz de Riesgos'!$A$20,""),3,100) | E6: =MID(IF(AND('Matriz de Riesgos'!$F$6=4,'Matriz de Riesgos'!$G$6=3),", "&'Matriz de Riesgos'!$A$6,"")&IF(AND('Matriz de Riesgos'!$F$7=4,'Matriz de Riesgos'!$G$7=3),", "&'Matriz de Riesgos'!$A$7,"")&IF(AND('Matriz de Riesgos'!$F$8=4,'Matriz de Riesgos'!$G$8=3),", "&'Matriz de Riesgos'!$A$8,"")&IF(AND('Matriz de Riesgos'!$F$9=4,'Matriz de Riesgos'!$G$9=3),", "&'Matriz de Riesgos'!$A$9,"")&IF(AND('Matriz de Riesgos'!$F$10=4,'Matriz de Riesgos'!$G$10=3),", "&'Matriz de Riesgos'!$A$10,"")&IF(AND('Matriz de Riesgos'!$F$11=4,'Matriz de Riesgos'!$G$11=3),", "&'Matriz de Riesgos'!$A$11,"")&IF(AND('Matriz de Riesgos'!$F$12=4,'Matriz de Riesgos'!$G$12=3),", "&'Matriz de Riesgos'!$A$12,"")&IF(AND('Matriz de Riesgos'!$F$13=4,'Matriz de Riesgos'!$G$13=3),", "&'Matriz de Riesgos'!$A$13,"")&IF(AND('Matriz de Riesgos'!$F$14=4,'Matriz de Riesgos'!$G$14=3),", "&'Matriz de Riesgos'!$A$14,"")&IF(AND('Matriz de Riesgos'!$F$15=4,'Matriz de Riesgos'!$G$15=3),", "&'Matriz de Riesgos'!$A$15,"")&IF(AND('Matriz de Riesgos'!$F$16=4,'Matriz de Riesgos'!$G$16=3),", "&'Matriz de Riesgos'!$A$16,"")&IF(AND('Matriz de Riesgos'!$F$17=4,'Matriz de Riesgos'!$G$17=3),", "&'Matriz de Riesgos'!$A$17,"")&IF(AND('Matriz de Riesgos'!$F$18=4,'Matriz de Riesgos'!$G$18=3),", "&'Matriz de Riesgos'!$A$18,"")&IF(AND('Matriz de Riesgos'!$F$19=4,'Matriz de Riesgos'!$G$19=3),", "&'Matriz de Riesgos'!$A$19,"")&IF(AND('Matriz de Riesgos'!$F$20=4,'Matriz de Riesgos'!$G$20=3),", "&'Matriz de Riesgos'!$A$20,""),3,100) -> 10 | F6: =MID(IF(AND('Matriz de Riesgos'!$F$6=4,'Matriz de Riesgos'!$G$6=4),", "&'Matriz de Riesgos'!$A$6,"")&IF(AND('Matriz de Riesgos'!$F$7=4,'Matriz de Riesgos'!$G$7=4),", "&'Matriz de Riesgos'!$A$7,"")&IF(AND('Matriz de Riesgos'!$F$8=4,'Matriz de Riesgos'!$G$8=4),", "&'Matriz de Riesgos'!$A$8,"")&IF(AND('Matriz de Riesgos'!$F$9=4,'Matriz de Riesgos'!$G$9=4),", "&'Matriz de Riesgos'!$A$9,"")&IF(AND('Matriz de Riesgos'!$F$10=4,'Matriz de Riesgos'!$G$10=4),", "&'Matriz de Riesgos'!$A$10,"")&IF(AND('Matriz de Riesgos'!$F$11=4,'Matriz de Riesgos'!$G$11=4),", "&'Matriz de Riesgos'!$A$11,"")&IF(AND('Matriz de Riesgos'!$F$12=4,'Matriz de Riesgos'!$G$12=4),", "&'Matriz de Riesgos'!$A$12,"")&IF(AND('Matriz de Riesgos'!$F$13=4,'Matriz de Riesgos'!$G$13=4),", "&'Matriz de Riesgos'!$A$13,"")&IF(AND('Matriz de Riesgos'!$F$14=4,'Matriz de Riesgos'!$G$14=4),", "&'Matriz de Riesgos'!$A$14,"")&IF(AND('Matriz de Riesgos'!$F$15=4,'Matriz de Riesgos'!$G$15=4),", "&'Matriz de Riesgos'!$A$15,"")&IF(AND('Matriz de Riesgos'!$F$16=4,'Matriz de Riesgos'!$G$16=4),", "&'Matriz de Riesgos'!$A$16,"")&IF(AND('Matriz de Riesgos'!$F$17=4,'Matriz de Riesgos'!$G$17=4),", "&'Matriz de Riesgos'!$A$17,"")&IF(AND('Matriz de Riesgos'!$F$18=4,'Matriz de Riesgos'!$G$18=4),", "&'Matriz de Riesgos'!$A$18,"")&IF(AND('Matriz de Riesgos'!$F$19=4,'Matriz de Riesgos'!$G$19=4),", "&'Matriz de Riesgos'!$A$19,"")&IF(AND('Matriz de Riesgos'!$F$20=4,'Matriz de Riesgos'!$G$20=4),", "&'Matriz de Riesgos'!$A$20,""),3,100) -> 7 | G6: =MID(IF(AND('Matriz de Riesgos'!$F$6=4,'Matriz de Riesgos'!$G$6=5),", "&'Matriz de Riesgos'!$A$6,"")&IF(AND('Matriz de Riesgos'!$F$7=4,'Matriz de Riesgos'!$G$7=5),", "&'Matriz de Riesgos'!$A$7,"")&IF(AND('Matriz de Riesgos'!$F$8=4,'Matriz de Riesgos'!$G$8=5),", "&'Matriz de Riesgos'!$A$8,"")&IF(AND('Matriz de Riesgos'!$F$9=4,'Matriz de Riesgos'!$G$9=5),", "&'Matriz de Riesgos'!$A$9,"")&IF(AND('Matriz de Riesgos'!$F$10=4,'Matriz de Riesgos'!$G$10=5),", "&'Matriz de Riesgos'!$A$10,"")&IF(AND('Matriz de Riesgos'!$F$11=4,'Matriz de Riesgos'!$G$11=5),", "&'Matriz de Riesgos'!$A$11,"")&IF(AND('Matriz de Riesgos'!$F$12=4,'Matriz de Riesgos'!$G$12=5),", "&'Matriz de Riesgos'!$A$12,"")&IF(AND('Matriz de Riesgos'!$F$13=4,'Matriz de Riesgos'!$G$13=5),", "&'Matriz de Riesgos'!$A$13,"")&IF(AND('Matriz de Riesgos'!$F$14=4,'Matriz de Riesgos'!$G$14=5),", "&'Matriz de Riesgos'!$A$14,"")&IF(AND('Matriz de Riesgos'!$F$15=4,'Matriz de Riesgos'!$G$15=5),", "&'Matriz de Riesgos'!$A$15,"")&IF(AND('Matriz de Riesgos'!$F$16=4,'Matriz de Riesgos'!$G$16=5),", "&'Matriz de Riesgos'!$A$16,"")&IF(AND('Matriz de Riesgos'!$F$17=4,'Matriz de Riesgos'!$G$17=5),", "&'Matriz de Riesgos'!$A$17,"")&IF(AND('Matriz de Riesgos'!$F$18=4,'Matriz de Riesgos'!$G$18=5),", "&'Matriz de Riesgos'!$A$18,"")&IF(AND('Matriz de Riesgos'!$F$19=4,'Matriz de Riesgos'!$G$19=5),", "&'Matriz de Riesgos'!$A$19,"")&IF(AND('Matriz de Riesgos'!$F$20=4,'Matriz de Riesgos'!$G$20=5),", "&'Matriz de Riesgos'!$A$20,""),3,100) -> 1, 14
B7: 3 Media | C7: =MID(IF(AND('Matriz de Riesgos'!$F$6=3,'Matriz de Riesgos'!$G$6=1),", "&'Matriz de Riesgos'!$A$6,"")&IF(AND('Matriz de Riesgos'!$F$7=3,'Matriz de Riesgos'!$G$7=1),", "&'Matriz de Riesgos'!$A$7,"")&IF(AND('Matriz de Riesgos'!$F$8=3,'Matriz de Riesgos'!$G$8=1),", "&'Matriz de Riesgos'!$A$8,"")&IF(AND('Matriz de Riesgos'!$F$9=3,'Matriz de Riesgos'!$G$9=1),", "&'Matriz de Riesgos'!$A$9,"")&IF(AND('Matriz de Riesgos'!$F$10=3,'Matriz de Riesgos'!$G$10=1),", "&'Matriz de Riesgos'!$A$10,"")&IF(AND('Matriz de Riesgos'!$F$11=3,'Matriz de Riesgos'!$G$11=1),", "&'Matriz de Riesgos'!$A$11,"")&IF(AND('Matriz de Riesgos'!$F$12=3,'Matriz de Riesgos'!$G$12=1),", "&'Matriz de Riesgos'!$A$12,"")&IF(AND('Matriz de Riesgos'!$F$13=3,'Matriz de Riesgos'!$G$13=1),", "&'Matriz de Riesgos'!$A$13,"")&IF(AND('Matriz de Riesgos'!$F$14=3,'Matriz de Riesgos'!$G$14=1),", "&'Matriz de Riesgos'!$A$14,"")&IF(AND('Matriz de Riesgos'!$F$15=3,'Matriz de Riesgos'!$G$15=1),", "&'Matriz de Riesgos'!$A$15,"")&IF(AND('Matriz de Riesgos'!$F$16=3,'Matriz de Riesgos'!$G$16=1),", "&'Matriz de Riesgos'!$A$16,"")&IF(AND('Matriz de Riesgos'!$F$17=3,'Matriz de Riesgos'!$G$17=1),", "&'Matriz de Riesgos'!$A$17,"")&IF(AND('Matriz de Riesgos'!$F$18=3,'Matriz de Riesgos'!$G$18=1),", "&'Matriz de Riesgos'!$A$18,"")&IF(AND('Matriz de Riesgos'!$F$19=3,'Matriz de Riesgos'!$G$19=1),", "&'Matriz de Riesgos'!$A$19,"")&IF(AND('Matriz de Riesgos'!$F$20=3,'Matriz de Riesgos'!$G$20=1),", "&'Matriz de Riesgos'!$A$20,""),3,100) | D7: =MID(IF(AND('Matriz de Riesgos'!$F$6=3,'Matriz de Riesgos'!$G$6=2),", "&'Matriz de Riesgos'!$A$6,"")&IF(AND('Matriz de Riesgos'!$F$7=3,'Matriz de Riesgos'!$G$7=2),", "&'Matriz de Riesgos'!$A$7,"")&IF(AND('Matriz de Riesgos'!$F$8=3,'Matriz de Riesgos'!$G$8=2),", "&'Matriz de Riesgos'!$A$8,"")&IF(AND('Matriz de Riesgos'!$F$9=3,'Matriz de Riesgos'!$G$9=2),", "&'Matriz de Riesgos'!$A$9,"")&IF(AND('Matriz de Riesgos'!$F$10=3,'Matriz de Riesgos'!$G$10=2),", "&'Matriz de Riesgos'!$A$10,"")&IF(AND('Matriz de Riesgos'!$F$11=3,'Matriz de Riesgos'!$G$11=2),", "&'Matriz de Riesgos'!$A$11,"")&IF(AND('Matriz de Riesgos'!$F$12=3,'Matriz de Riesgos'!$G$12=2),", "&'Matriz de Riesgos'!$A$12,"")&IF(AND('Matriz de Riesgos'!$F$13=3,'Matriz de Riesgos'!$G$13=2),", "&'Matriz de Riesgos'!$A$13,"")&IF(AND('Matriz de Riesgos'!$F$14=3,'Matriz de Riesgos'!$G$14=2),", "&'Matriz de Riesgos'!$A$14,"")&IF(AND('Matriz de Riesgos'!$F$15=3,'Matriz de Riesgos'!$G$15=2),", "&'Matriz de Riesgos'!$A$15,"")&IF(AND('Matriz de Riesgos'!$F$16=3,'Matriz de Riesgos'!$G$16=2),", "&'Matriz de Riesgos'!$A$16,"")&IF(AND('Matriz de Riesgos'!$F$17=3,'Matriz de Riesgos'!$G$17=2),", "&'Matriz de Riesgos'!$A$17,"")&IF(AND('Matriz de Riesgos'!$F$18=3,'Matriz de Riesgos'!$G$18=2),", "&'Matriz de Riesgos'!$A$18,"")&IF(AND('Matriz de Riesgos'!$F$19=3,'Matriz de Riesgos'!$G$19=2),", "&'Matriz de Riesgos'!$A$19,"")&IF(AND('Matriz de Riesgos'!$F$20=3,'Matriz de Riesgos'!$G$20=2),", "&'Matriz de Riesgos'!$A$20,""),3,100) | E7: =MID(IF(AND('Matriz de Riesgos'!$F$6=3,'Matriz de Riesgos'!$G$6=3),", "&'Matriz de Riesgos'!$A$6,"")&IF(AND('Matriz de Riesgos'!$F$7=3,'Matriz de Riesgos'!$G$7=3),", "&'Matriz de Riesgos'!$A$7,"")&IF(AND('Matriz de Riesgos'!$F$8=3,'Matriz de Riesgos'!$G$8=3),", "&'Matriz de Riesgos'!$A$8,"")&IF(AND('Matriz de Riesgos'!$F$9=3,'Matriz de Riesgos'!$G$9=3),", "&'Matriz de Riesgos'!$A$9,"")&IF(AND('Matriz de Riesgos'!$F$10=3,'Matriz de Riesgos'!$G$10=3),", "&'Matriz de Riesgos'!$A$10,"")&IF(AND('Matriz de Riesgos'!$F$11=3,'Matriz de Riesgos'!$G$11=3),", "&'Matriz de Riesgos'!$A$11,"")&IF(AND('Matriz de Riesgos'!$F$12=3,'Matriz de Riesgos'!$G$12=3),", "&'Matriz de Riesgos'!$A$12,"")&IF(AND('Matriz de Riesgos'!$F$13=3,'Matriz de Riesgos'!$G$13=3),", "&'Matriz de Riesgos'!$A$13,"")&IF(AND('Matriz de Riesgos'!$F$14=3,'Matriz de Riesgos'!$G$14=3),", "&'Matriz de Riesgos'!$A$14,"")&IF(AND('Matriz de Riesgos'!$F$15=3,'Matriz de Riesgos'!$G$15=3),", "&'Matriz de Riesgos'!$A$15,"")&IF(AND('Matriz de Riesgos'!$F$16=3,'Matriz de Riesgos'!$G$16=3),", "&'Matriz de Riesgos'!$A$16,"")&IF(AND('Matriz de Riesgos'!$F$17=3,'Matriz de Riesgos'!$G$17=3),", "&'Matriz de Riesgos'!$A$17,"")&IF(AND('Matriz de Riesgos'!$F$18=3,'Matriz de Riesgos'!$G$18=3),", "&'Matriz de Riesgos'!$A$18,"")&IF(AND('Matriz de Riesgos'!$F$19=3,'Matriz de Riesgos'!$G$19=3),", "&'Matriz de Riesgos'!$A$19,"")&IF(AND('Matriz de Riesgos'!$F$20=3,'Matriz de Riesgos'!$G$20=3),", "&'Matriz de Riesgos'!$A$20,""),3,100) -> 5, 8, 12 | F7: =MID(IF(AND('Matriz de Riesgos'!$F$6=3,'Matriz de Riesgos'!$G$6=4),", "&'Matriz de Riesgos'!$A$6,"")&IF(AND('Matriz de Riesgos'!$F$7=3,'Matriz de Riesgos'!$G$7=4),", "&'Matriz de Riesgos'!$A$7,"")&IF(AND('Matriz de Riesgos'!$F$8=3,'Matriz de Riesgos'!$G$8=4),", "&'Matriz de Riesgos'!$A$8,"")&IF(AND('Matriz de Riesgos'!$F$9=3,'Matriz de Riesgos'!$G$9=4),", "&'Matriz de Riesgos'!$A$9,"")&IF(AND('Matriz de Riesgos'!$F$10=3,'Matriz de Riesgos'!$G$10=4),", "&'Matriz de Riesgos'!$A$10,"")&IF(AND('Matriz de Riesgos'!$F$11=3,'Matriz de Riesgos'!$G$11=4),", "&'Matriz de Riesgos'!$A$11,"")&IF(AND('Matriz de Riesgos'!$F$12=3,'Matriz de Riesgos'!$G$12=4),", "&'Matriz de Riesgos'!$A$12,"")&IF(AND('Matriz de Riesgos'!$F$13=3,'Matriz de Riesgos'!$G$13=4),", "&'Matriz de Riesgos'!$A$13,"")&IF(AND('Matriz de Riesgos'!$F$14=3,'Matriz de Riesgos'!$G$14=4),", "&'Matriz de Riesgos'!$A$14,"")&IF(AND('Matriz de Riesgos'!$F$15=3,'Matriz de Riesgos'!$G$15=4),", "&'Matriz de Riesgos'!$A$15,"")&IF(AND('Matriz de Riesgos'!$F$16=3,'Matriz de Riesgos'!$G$16=4),", "&'Matriz de Riesgos'!$A$16,"")&IF(AND('Matriz de Riesgos'!$F$17=3,'Matriz de Riesgos'!$G$17=4),", "&'Matriz de Riesgos'!$A$17,"")&IF(AND('Matriz de Riesgos'!$F$18=3,'Matriz de Riesgos'!$G$18=4),", "&'Matriz de Riesgos'!$A$18,"")&IF(AND('Matriz de Riesgos'!$F$19=3,'Matriz de Riesgos'!$G$19=4),", "&'Matriz de Riesgos'!$A$19,"")&IF(AND('Matriz de Riesgos'!$F$20=3,'Matriz de Riesgos'!$G$20=4),", "&'Matriz de Riesgos'!$A$20,""),3,100) -> 4, 9, 11, 15 | G7: =MID(IF(AND('Matriz de Riesgos'!$F$6=3,'Matriz de Riesgos'!$G$6=5),", "&'Matriz de Riesgos'!$A$6,"")&IF(AND('Matriz de Riesgos'!$F$7=3,'Matriz de Riesgos'!$G$7=5),", "&'Matriz de Riesgos'!$A$7,"")&IF(AND('Matriz de Riesgos'!$F$8=3,'Matriz de Riesgos'!$G$8=5),", "&'Matriz de Riesgos'!$A$8,"")&IF(AND('Matriz de Riesgos'!$F$9=3,'Matriz de Riesgos'!$G$9=5),", "&'Matriz de Riesgos'!$A$9,"")&IF(AND('Matriz de Riesgos'!$F$10=3,'Matriz de Riesgos'!$G$10=5),", "&'Matriz de Riesgos'!$A$10,"")&IF(AND('Matriz de Riesgos'!$F$11=3,'Matriz de Riesgos'!$G$11=5),", "&'Matriz de Riesgos'!$A$11,"")&IF(AND('Matriz de Riesgos'!$F$12=3,'Matriz de Riesgos'!$G$12=5),", "&'Matriz de Riesgos'!$A$12,"")&IF(AND('Matriz de Riesgos'!$F$13=3,'Matriz de Riesgos'!$G$13=5),", "&'Matriz de Riesgos'!$A$13,"")&IF(AND('Matriz de Riesgos'!$F$14=3,'Matriz de Riesgos'!$G$14=5),", "&'Matriz de Riesgos'!$A$14,"")&IF(AND('Matriz de Riesgos'!$F$15=3,'Matriz de Riesgos'!$G$15=5),", "&'Matriz de Riesgos'!$A$15,"")&IF(AND('Matriz de Riesgos'!$F$16=3,'Matriz de Riesgos'!$G$16=5),", "&'Matriz de Riesgos'!$A$16,"")&IF(AND('Matriz de Riesgos'!$F$17=3,'Matriz de Riesgos'!$G$17=5),", "&'Matriz de Riesgos'!$A$17,"")&IF(AND('Matriz de Riesgos'!$F$18=3,'Matriz de Riesgos'!$G$18=5),", "&'Matriz de Riesgos'!$A$18,"")&IF(AND('Matriz de Riesgos'!$F$19=3,'Matriz de Riesgos'!$G$19=5),", "&'Matriz de Riesgos'!$A$19,"")&IF(AND('Matriz de Riesgos'!$F$20=3,'Matriz de Riesgos'!$G$20=5),", "&'Matriz de Riesgos'!$A$20,""),3,100) -> 2, 3, 6
B8: 2 Baja | C8: =MID(IF(AND('Matriz de Riesgos'!$F$6=2,'Matriz de Riesgos'!$G$6=1),", "&'Matriz de Riesgos'!$A$6,"")&IF(AND('Matriz de Riesgos'!$F$7=2,'Matriz de Riesgos'!$G$7=1),", "&'Matriz de Riesgos'!$A$7,"")&IF(AND('Matriz de Riesgos'!$F$8=2,'Matriz de Riesgos'!$G$8=1),", "&'Matriz de Riesgos'!$A$8,"")&IF(AND('Matriz de Riesgos'!$F$9=2,'Matriz de Riesgos'!$G$9=1),", "&'Matriz de Riesgos'!$A$9,"")&IF(AND('Matriz de Riesgos'!$F$10=2,'Matriz de Riesgos'!$G$10=1),", "&'Matriz de Riesgos'!$A$10,"")&IF(AND('Matriz de Riesgos'!$F$11=2,'Matriz de Riesgos'!$G$11=1),", "&'Matriz de Riesgos'!$A$11,"")&IF(AND('Matriz de Riesgos'!$F$12=2,'Matriz de Riesgos'!$G$12=1),", "&'Matriz de Riesgos'!$A$12,"")&IF(AND('Matriz de Riesgos'!$F$13=2,'Matriz de Riesgos'!$G$13=1),", "&'Matriz de Riesgos'!$A$13,"")&IF(AND('Matriz de Riesgos'!$F$14=2,'Matriz de Riesgos'!$G$14=1),", "&'Matriz de Riesgos'!$A$14,"")&IF(AND('Matriz de Riesgos'!$F$15=2,'Matriz de Riesgos'!$G$15=1),", "&'Matriz de Riesgos'!$A$15,"")&IF(AND('Matriz de Riesgos'!$F$16=2,'Matriz de Riesgos'!$G$16=1),", "&'Matriz de Riesgos'!$A$16,"")&IF(AND('Matriz de Riesgos'!$F$17=2,'Matriz de Riesgos'!$G$17=1),", "&'Matriz de Riesgos'!$A$17,"")&IF(AND('Matriz de Riesgos'!$F$18=2,'Matriz de Riesgos'!$G$18=1),", "&'Matriz de Riesgos'!$A$18,"")&IF(AND('Matriz de Riesgos'!$F$19=2,'Matriz de Riesgos'!$G$19=1),", "&'Matriz de Riesgos'!$A$19,"")&IF(AND('Matriz de Riesgos'!$F$20=2,'Matriz de Riesgos'!$G$20=1),", "&'Matriz de Riesgos'!$A$20,""),3,100) | D8: =MID(IF(AND('Matriz de Riesgos'!$F$6=2,'Matriz de Riesgos'!$G$6=2),", "&'Matriz de Riesgos'!$A$6,"")&IF(AND('Matriz de Riesgos'!$F$7=2,'Matriz de Riesgos'!$G$7=2),", "&'Matriz de Riesgos'!$A$7,"")&IF(AND('Matriz de Riesgos'!$F$8=2,'Matriz de Riesgos'!$G$8=2),", "&'Matriz de Riesgos'!$A$8,"")&IF(AND('Matriz de Riesgos'!$F$9=2,'Matriz de Riesgos'!$G$9=2),", "&'Matriz de Riesgos'!$A$9,"")&IF(AND('Matriz de Riesgos'!$F$10=2,'Matriz de Riesgos'!$G$10=2),", "&'Matriz de Riesgos'!$A$10,"")&IF(AND('Matriz de Riesgos'!$F$11=2,'Matriz de Riesgos'!$G$11=2),", "&'Matriz de Riesgos'!$A$11,"")&IF(AND('Matriz de Riesgos'!$F$12=2,'Matriz de Riesgos'!$G$12=2),", "&'Matriz de Riesgos'!$A$12,"")&IF(AND('Matriz de Riesgos'!$F$13=2,'Matriz de Riesgos'!$G$13=2),", "&'Matriz de Riesgos'!$A$13,"")&IF(AND('Matriz de Riesgos'!$F$14=2,'Matriz de Riesgos'!$G$14=2),", "&'Matriz de Riesgos'!$A$14,"")&IF(AND('Matriz de Riesgos'!$F$15=2,'Matriz de Riesgos'!$G$15=2),", "&'Matriz de Riesgos'!$A$15,"")&IF(AND('Matriz de Riesgos'!$F$16=2,'Matriz de Riesgos'!$G$16=2),", "&'Matriz de Riesgos'!$A$16,"")&IF(AND('Matriz de Riesgos'!$F$17=2,'Matriz de Riesgos'!$G$17=2),", "&'Matriz de Riesgos'!$A$17,"")&IF(AND('Matriz de Riesgos'!$F$18=2,'Matriz de Riesgos'!$G$18=2),", "&'Matriz de Riesgos'!$A$18,"")&IF(AND('Matriz de Riesgos'!$F$19=2,'Matriz de Riesgos'!$G$19=2),", "&'Matriz de Riesgos'!$A$19,"")&IF(AND('Matriz de Riesgos'!$F$20=2,'Matriz de Riesgos'!$G$20=2),", "&'Matriz de Riesgos'!$A$20,""),3,100) | E8: =MID(IF(AND('Matriz de Riesgos'!$F$6=2,'Matriz de Riesgos'!$G$6=3),", "&'Matriz de Riesgos'!$A$6,"")&IF(AND('Matriz de Riesgos'!$F$7=2,'Matriz de Riesgos'!$G$7=3),", "&'Matriz de Riesgos'!$A$7,"")&IF(AND('Matriz de Riesgos'!$F$8=2,'Matriz de Riesgos'!$G$8=3),", "&'Matriz de Riesgos'!$A$8,"")&IF(AND('Matriz de Riesgos'!$F$9=2,'Matriz de Riesgos'!$G$9=3),", "&'Matriz de Riesgos'!$A$9,"")&IF(AND('Matriz de Riesgos'!$F$10=2,'Matriz de Riesgos'!$G$10=3),", "&'Matriz de Riesgos'!$A$10,"")&IF(AND('Matriz de Riesgos'!$F$11=2,'Matriz de Riesgos'!$G$11=3),", "&'Matriz de Riesgos'!$A$11,"")&IF(AND('Matriz de Riesgos'!$F$12=2,'Matriz de Riesgos'!$G$12=3),", "&'Matriz de Riesgos'!$A$12,"")&IF(AND('Matriz de Riesgos'!$F$13=2,'Matriz de Riesgos'!$G$13=3),", "&'Matriz de Riesgos'!$A$13,"")&IF(AND('Matriz de Riesgos'!$F$14=2,'Matriz de Riesgos'!$G$14=3),", "&'Matriz de Riesgos'!$A$14,"")&IF(AND('Matriz de Riesgos'!$F$15=2,'Matriz de Riesgos'!$G$15=3),", "&'Matriz de Riesgos'!$A$15,"")&IF(AND('Matriz de Riesgos'!$F$16=2,'Matriz de Riesgos'!$G$16=3),", "&'Matriz de Riesgos'!$A$16,"")&IF(AND('Matriz de Riesgos'!$F$17=2,'Matriz de Riesgos'!$G$17=3),", "&'Matriz de Riesgos'!$A$17,"")&IF(AND('Matriz de Riesgos'!$F$18=2,'Matriz de Riesgos'!$G$18=3),", "&'Matriz de Riesgos'!$A$18,"")&IF(AND('Matriz de Riesgos'!$F$19=2,'Matriz de Riesgos'!$G$19=3),", "&'Matriz de Riesgos'!$A$19,"")&IF(AND('Matriz de Riesgos'!$F$20=2,'Matriz de Riesgos'!$G$20=3),", "&'Matriz de Riesgos'!$A$20,""),3,100) | F8: =MID(IF(AND('Matriz de Riesgos'!$F$6=2,'Matriz de Riesgos'!$G$6=4),", "&'Matriz de Riesgos'!$A$6,"")&IF(AND('Matriz de Riesgos'!$F$7=2,'Matriz de Riesgos'!$G$7=4),", "&'Matriz de Riesgos'!$A$7,"")&IF(AND('Matriz de Riesgos'!$F$8=2,'Matriz de Riesgos'!$G$8=4),", "&'Matriz de Riesgos'!$A$8,"")&IF(AND('Matriz de Riesgos'!$F$9=2,'Matriz de Riesgos'!$G$9=4),", "&'Matriz de Riesgos'!$A$9,"")&IF(AND('Matriz de Riesgos'!$F$10=2,'Matriz de Riesgos'!$G$10=4),", "&'Matriz de Riesgos'!$A$10,"")&IF(AND('Matriz de Riesgos'!$F$11=2,'Matriz de Riesgos'!$G$11=4),", "&'Matriz de Riesgos'!$A$11,"")&IF(AND('Matriz de Riesgos'!$F$12=2,'Matriz de Riesgos'!$G$12=4),", "&'Matriz de Riesgos'!$A$12,"")&IF(AND('Matriz de Riesgos'!$F$13=2,'Matriz de Riesgos'!$G$13=4),", "&'Matriz de Riesgos'!$A$13,"")&IF(AND('Matriz de Riesgos'!$F$14=2,'Matriz de Riesgos'!$G$14=4),", "&'Matriz de Riesgos'!$A$14,"")&IF(AND('Matriz de Riesgos'!$F$15=2,'Matriz de Riesgos'!$G$15=4),", "&'Matriz de Riesgos'!$A$15,"")&IF(AND('Matriz de Riesgos'!$F$16=2,'Matriz de Riesgos'!$G$16=4),", "&'Matriz de Riesgos'!$A$16,"")&IF(AND('Matriz de Riesgos'!$F$17=2,'Matriz de Riesgos'!$G$17=4),", "&'Matriz de Riesgos'!$A$17,"")&IF(AND('Matriz de Riesgos'!$F$18=2,'Matriz de Riesgos'!$G$18=4),", "&'Matriz de Riesgos'!$A$18,"")&IF(AND('Matriz de Riesgos'!$F$19=2,'Matriz de Riesgos'!$G$19=4),", "&'Matriz de Riesgos'!$A$19,"")&IF(AND('Matriz de Riesgos'!$F$20=2,'Matriz de Riesgos'!$G$20=4),", "&'Matriz de Riesgos'!$A$20,""),3,100) -> 13 | G8: =MID(IF(AND('Matriz de Riesgos'!$F$6=2,'Matriz de Riesgos'!$G$6=5),", "&'Matriz de Riesgos'!$A$6,"")&IF(AND('Matriz de Riesgos'!$F$7=2,'Matriz de Riesgos'!$G$7=5),", "&'Matriz de Riesgos'!$A$7,"")&IF(AND('Matriz de Riesgos'!$F$8=2,'Matriz de Riesgos'!$G$8=5),", "&'Matriz de Riesgos'!$A$8,"")&IF(AND('Matriz de Riesgos'!$F$9=2,'Matriz de Riesgos'!$G$9=5),", "&'Matriz de Riesgos'!$A$9,"")&IF(AND('Matriz de Riesgos'!$F$10=2,'Matriz de Riesgos'!$G$10=5),", "&'Matriz de Riesgos'!$A$10,"")&IF(AND('Matriz de Riesgos'!$F$11=2,'Matriz de Riesgos'!$G$11=5),", "&'Matriz de Riesgos'!$A$11,"")&IF(AND('Matriz de Riesgos'!$F$12=2,'Matriz de Riesgos'!$G$12=5),", "&'Matriz de Riesgos'!$A$12,"")&IF(AND('Matriz de Riesgos'!$F$13=2,'Matriz de Riesgos'!$G$13=5),", "&'Matriz de Riesgos'!$A$13,"")&IF(AND('Matriz de Riesgos'!$F$14=2,'Matriz de Riesgos'!$G$14=5),", "&'Matriz de Riesgos'!$A$14,"")&IF(AND('Matriz de Riesgos'!$F$15=2,'Matriz de Riesgos'!$G$15=5),", "&'Matriz de Riesgos'!$A$15,"")&IF(AND('Matriz de Riesgos'!$F$16=2,'Matriz de Riesgos'!$G$16=5),", "&'Matriz de Riesgos'!$A$16,"")&IF(AND('Matriz de Riesgos'!$F$17=2,'Matriz de Riesgos'!$G$17=5),", "&'Matriz de Riesgos'!$A$17,"")&IF(AND('Matriz de Riesgos'!$F$18=2,'Matriz de Riesgos'!$G$18=5),", "&'Matriz de Riesgos'!$A$18,"")&IF(AND('Matriz de Riesgos'!$F$19=2,'Matriz de Riesgos'!$G$19=5),", "&'Matriz de Riesgos'!$A$19,"")&IF(AND('Matriz de Riesgos'!$F$20=2,'Matriz de Riesgos'!$G$20=5),", "&'Matriz de Riesgos'!$A$20,""),3,100)
B9: 1 Muy baja | C9: =MID(IF(AND('Matriz de Riesgos'!$F$6=1,'Matriz de Riesgos'!$G$6=1),", "&'Matriz de Riesgos'!$A$6,"")&IF(AND('Matriz de Riesgos'!$F$7=1,'Matriz de Riesgos'!$G$7=1),", "&'Matriz de Riesgos'!$A$7,"")&IF(AND('Matriz de Riesgos'!$F$8=1,'Matriz de Riesgos'!$G$8=1),", "&'Matriz de Riesgos'!$A$8,"")&IF(AND('Matriz de Riesgos'!$F$9=1,'Matriz de Riesgos'!$G$9=1),", "&'Matriz de Riesgos'!$A$9,"")&IF(AND('Matriz de Riesgos'!$F$10=1,'Matriz de Riesgos'!$G$10=1),", "&'Matriz de Riesgos'!$A$10,"")&IF(AND('Matriz de Riesgos'!$F$11=1,'Matriz de Riesgos'!$G$11=1),", "&'Matriz de Riesgos'!$A$11,"")&IF(AND('Matriz de Riesgos'!$F$12=1,'Matriz de Riesgos'!$G$12=1),", "&'Matriz de Riesgos'!$A$12,"")&IF(AND('Matriz de Riesgos'!$F$13=1,'Matriz de Riesgos'!$G$13=1),", "&'Matriz de Riesgos'!$A$13,"")&IF(AND('Matriz de Riesgos'!$F$14=1,'Matriz de Riesgos'!$G$14=1),", "&'Matriz de Riesgos'!$A$14,"")&IF(AND('Matriz de Riesgos'!$F$15=1,'Matriz de Riesgos'!$G$15=1),", "&'Matriz de Riesgos'!$A$15,"")&IF(AND('Matriz de Riesgos'!$F$16=1,'Matriz de Riesgos'!$G$16=1),", "&'Matriz de Riesgos'!$A$16,"")&IF(AND('Matriz de Riesgos'!$F$17=1,'Matriz de Riesgos'!$G$17=1),", "&'Matriz de Riesgos'!$A$17,"")&IF(AND('Matriz de Riesgos'!$F$18=1,'Matriz de Riesgos'!$G$18=1),", "&'Matriz de Riesgos'!$A$18,"")&IF(AND('Matriz de Riesgos'!$F$19=1,'Matriz de Riesgos'!$G$19=1),", "&'Matriz de Riesgos'!$A$19,"")&IF(AND('Matriz de Riesgos'!$F$20=1,'Matriz de Riesgos'!$G$20=1),", "&'Matriz de Riesgos'!$A$20,""),3,100) | D9: =MID(IF(AND('Matriz de Riesgos'!$F$6=1,'Matriz de Riesgos'!$G$6=2),", "&'Matriz de Riesgos'!$A$6,"")&IF(AND('Matriz de Riesgos'!$F$7=1,'Matriz de Riesgos'!$G$7=2),", "&'Matriz de Riesgos'!$A$7,"")&IF(AND('Matriz de Riesgos'!$F$8=1,'Matriz de Riesgos'!$G$8=2),", "&'Matriz de Riesgos'!$A$8,"")&IF(AND('Matriz de Riesgos'!$F$9=1,'Matriz de Riesgos'!$G$9=2),", "&'Matriz de Riesgos'!$A$9,"")&IF(AND('Matriz de Riesgos'!$F$10=1,'Matriz de Riesgos'!$G$10=2),", "&'Matriz de Riesgos'!$A$10,"")&IF(AND('Matriz de Riesgos'!$F$11=1,'Matriz de Riesgos'!$G$11=2),", "&'Matriz de Riesgos'!$A$11,"")&IF(AND('Matriz de Riesgos'!$F$12=1,'Matriz de Riesgos'!$G$12=2),", "&'Matriz de Riesgos'!$A$12,"")&IF(AND('Matriz de Riesgos'!$F$13=1,'Matriz de Riesgos'!$G$13=2),", "&'Matriz de Riesgos'!$A$13,"")&IF(AND('Matriz de Riesgos'!$F$14=1,'Matriz de Riesgos'!$G$14=2),", "&'Matriz de Riesgos'!$A$14,"")&IF(AND('Matriz de Riesgos'!$F$15=1,'Matriz de Riesgos'!$G$15=2),", "&'Matriz de Riesgos'!$A$15,"")&IF(AND('Matriz de Riesgos'!$F$16=1,'Matriz de Riesgos'!$G$16=2),", "&'Matriz de Riesgos'!$A$16,"")&IF(AND('Matriz de Riesgos'!$F$17=1,'Matriz de Riesgos'!$G$17=2),", "&'Matriz de Riesgos'!$A$17,"")&IF(AND('Matriz de Riesgos'!$F$18=1,'Matriz de Riesgos'!$G$18=2),", "&'Matriz de Riesgos'!$A$18,"")&IF(AND('Matriz de Riesgos'!$F$19=1,'Matriz de Riesgos'!$G$19=2),", "&'Matriz de Riesgos'!$A$19,"")&IF(AND('Matriz de Riesgos'!$F$20=1,'Matriz de Riesgos'!$G$20=2),", "&'Matriz de Riesgos'!$A$20,""),3,100) | E9: =MID(IF(AND('Matriz de Riesgos'!$F$6=1,'Matriz de Riesgos'!$G$6=3),", "&'Matriz de Riesgos'!$A$6,"")&IF(AND('Matriz de Riesgos'!$F$7=1,'Matriz de Riesgos'!$G$7=3),", "&'Matriz de Riesgos'!$A$7,"")&IF(AND('Matriz de Riesgos'!$F$8=1,'Matriz de Riesgos'!$G$8=3),", "&'Matriz de Riesgos'!$A$8,"")&IF(AND('Matriz de Riesgos'!$F$9=1,'Matriz de Riesgos'!$G$9=3),", "&'Matriz de Riesgos'!$A$9,"")&IF(AND('Matriz de Riesgos'!$F$10=1,'Matriz de Riesgos'!$G$10=3),", "&'Matriz de Riesgos'!$A$10,"")&IF(AND('Matriz de Riesgos'!$F$11=1,'Matriz de Riesgos'!$G$11=3),", "&'Matriz de Riesgos'!$A$11,"")&IF(AND('Matriz de Riesgos'!$F$12=1,'Matriz de Riesgos'!$G$12=3),", "&'Matriz de Riesgos'!$A$12,"")&IF(AND('Matriz de Riesgos'!$F$13=1,'Matriz de Riesgos'!$G$13=3),", "&'Matriz de Riesgos'!$A$13,"")&IF(AND('Matriz de Riesgos'!$F$14=1,'Matriz de Riesgos'!$G$14=3),", "&'Matriz de Riesgos'!$A$14,"")&IF(AND('Matriz de Riesgos'!$F$15=1,'Matriz de Riesgos'!$G$15=3),", "&'Matriz de Riesgos'!$A$15,"")&IF(AND('Matriz de Riesgos'!$F$16=1,'Matriz de Riesgos'!$G$16=3),", "&'Matriz de Riesgos'!$A$16,"")&IF(AND('Matriz de Riesgos'!$F$17=1,'Matriz de Riesgos'!$G$17=3),", "&'Matriz de Riesgos'!$A$17,"")&IF(AND('Matriz de Riesgos'!$F$18=1,'Matriz de Riesgos'!$G$18=3),", "&'Matriz de Riesgos'!$A$18,"")&IF(AND('Matriz de Riesgos'!$F$19=1,'Matriz de Riesgos'!$G$19=3),", "&'Matriz de Riesgos'!$A$19,"")&IF(AND('Matriz de Riesgos'!$F$20=1,'Matriz de Riesgos'!$G$20=3),", "&'Matriz de Riesgos'!$A$20,""),3,100) | F9: =MID(IF(AND('Matriz de Riesgos'!$F$6=1,'Matriz de Riesgos'!$G$6=4),", "&'Matriz de Riesgos'!$A$6,"")&IF(AND('Matriz de Riesgos'!$F$7=1,'Matriz de Riesgos'!$G$7=4),", "&'Matriz de Riesgos'!$A$7,"")&IF(AND('Matriz de Riesgos'!$F$8=1,'Matriz de Riesgos'!$G$8=4),", "&'Matriz de Riesgos'!$A$8,"")&IF(AND('Matriz de Riesgos'!$F$9=1,'Matriz de Riesgos'!$G$9=4),", "&'Matriz de Riesgos'!$A$9,"")&IF(AND('Matriz de Riesgos'!$F$10=1,'Matriz de Riesgos'!$G$10=4),", "&'Matriz de Riesgos'!$A$10,"")&IF(AND('Matriz de Riesgos'!$F$11=1,'Matriz de Riesgos'!$G$11=4),", "&'Matriz de Riesgos'!$A$11,"")&IF(AND('Matriz de Riesgos'!$F$12=1,'Matriz de Riesgos'!$G$12=4),", "&'Matriz de Riesgos'!$A$12,"")&IF(AND('Matriz de Riesgos'!$F$13=1,'Matriz de Riesgos'!$G$13=4),", "&'Matriz de Riesgos'!$A$13,"")&IF(AND('Matriz de Riesgos'!$F$14=1,'Matriz de Riesgos'!$G$14=4),", "&'Matriz de Riesgos'!$A$14,"")&IF(AND('Matriz de Riesgos'!$F$15=1,'Matriz de Riesgos'!$G$15=4),", "&'Matriz de Riesgos'!$A$15,"")&IF(AND('Matriz de Riesgos'!$F$16=1,'Matriz de Riesgos'!$G$16=4),", "&'Matriz de Riesgos'!$A$16,"")&IF(AND('Matriz de Riesgos'!$F$17=1,'Matriz de Riesgos'!$G$17=4),", "&'Matriz de Riesgos'!$A$17,"")&IF(AND('Matriz de Riesgos'!$F$18=1,'Matriz de Riesgos'!$G$18=4),", "&'Matriz de Riesgos'!$A$18,"")&IF(AND('Matriz de Riesgos'!$F$19=1,'Matriz de Riesgos'!$G$19=4),", "&'Matriz de Riesgos'!$A$19,"")&IF(AND('Matriz de Riesgos'!$F$20=1,'Matriz de Riesgos'!$G$20=4),", "&'Matriz de Riesgos'!$A$20,""),3,100) | G9: =MID(IF(AND('Matriz de Riesgos'!$F$6=1,'Matriz de Riesgos'!$G$6=5),", "&'Matriz de Riesgos'!$A$6,"")&IF(AND('Matriz de Riesgos'!$F$7=1,'Matriz de Riesgos'!$G$7=5),", "&'Matriz de Riesgos'!$A$7,"")&IF(AND('Matriz de Riesgos'!$F$8=1,'Matriz de Riesgos'!$G$8=5),", "&'Matriz de Riesgos'!$A$8,"")&IF(AND('Matriz de Riesgos'!$F$9=1,'Matriz de Riesgos'!$G$9=5),", "&'Matriz de Riesgos'!$A$9,"")&IF(AND('Matriz de Riesgos'!$F$10=1,'Matriz de Riesgos'!$G$10=5),", "&'Matriz de Riesgos'!$A$10,"")&IF(AND('Matriz de Riesgos'!$F$11=1,'Matriz de Riesgos'!$G$11=5),", "&'Matriz de Riesgos'!$A$11,"")&IF(AND('Matriz de Riesgos'!$F$12=1,'Matriz de Riesgos'!$G$12=5),", "&'Matriz de Riesgos'!$A$12,"")&IF(AND('Matriz de Riesgos'!$F$13=1,'Matriz de Riesgos'!$G$13=5),", "&'Matriz de Riesgos'!$A$13,"")&IF(AND('Matriz de Riesgos'!$F$14=1,'Matriz de Riesgos'!$G$14=5),", "&'Matriz de Riesgos'!$A$14,"")&IF(AND('Matriz de Riesgos'!$F$15=1,'Matriz de Riesgos'!$G$15=5),", "&'Matriz de Riesgos'!$A$15,"")&IF(AND('Matriz de Riesgos'!$F$16=1,'Matriz de Riesgos'!$G$16=5),", "&'Matriz de Riesgos'!$A$16,"")&IF(AND('Matriz de Riesgos'!$F$17=1,'Matriz de Riesgos'!$G$17=5),", "&'Matriz de Riesgos'!$A$17,"")&IF(AND('Matriz de Riesgos'!$F$18=1,'Matriz de Riesgos'!$G$18=5),", "&'Matriz de Riesgos'!$A$18,"")&IF(AND('Matriz de Riesgos'!$F$19=1,'Matriz de Riesgos'!$G$19=5),", "&'Matriz de Riesgos'!$A$19,"")&IF(AND('Matriz de Riesgos'!$F$20=1,'Matriz de Riesgos'!$G$20=5),", "&'Matriz de Riesgos'!$A$20,""),3,100)
C10: IMPACTO
B12: Nivel | C12: Rango | D12: Riesgos hoy
B13: Crítico | C13: 15-25 | D13: =COUNTIF('Matriz de Riesgos'!$I$6:$I$20,B13) -> 6
B14: Alto | C14: 10-14 | D14: =COUNTIF('Matriz de Riesgos'!$I$6:$I$20,B14) -> 5
B15: Medio | C15: 5-9 | D15: =COUNTIF('Matriz de Riesgos'!$I$6:$I$20,B15) -> 4
B16: Bajo | C16: 1-4 | D16: =COUNTIF('Matriz de Riesgos'!$I$6:$I$20,B16) -> 0
B19: ID | C19: Nivel (P × I)
B20: =" R"&'Matriz de Riesgos'!A6 -> R1 | C20: ='Matriz de Riesgos'!H6 -> 20
B21: =" R"&'Matriz de Riesgos'!A7 -> R2 | C21: ='Matriz de Riesgos'!H7 -> 15
B22: =" R"&'Matriz de Riesgos'!A8 -> R3 | C22: ='Matriz de Riesgos'!H8 -> 15
B23: =" R"&'Matriz de Riesgos'!A9 -> R4 | C23: ='Matriz de Riesgos'!H9 -> 12
B24: =" R"&'Matriz de Riesgos'!A10 -> R5 | C24: ='Matriz de Riesgos'!H10 -> 9
B25: =" R"&'Matriz de Riesgos'!A11 -> R6 | C25: ='Matriz de Riesgos'!H11 -> 15
B26: =" R"&'Matriz de Riesgos'!A12 -> R7 | C26: ='Matriz de Riesgos'!H12 -> 16
B27: =" R"&'Matriz de Riesgos'!A13 -> R8 | C27: ='Matriz de Riesgos'!H13 -> 9
B28: =" R"&'Matriz de Riesgos'!A14 -> R9 | C28: ='Matriz de Riesgos'!H14 -> 12
B29: =" R"&'Matriz de Riesgos'!A15 -> R10 | C29: ='Matriz de Riesgos'!H15 -> 12
B30: =" R"&'Matriz de Riesgos'!A16 -> R11 | C30: ='Matriz de Riesgos'!H16 -> 12
B31: =" R"&'Matriz de Riesgos'!A17 -> R12 | C31: ='Matriz de Riesgos'!H17 -> 9
