Workbook

Sheet Alto Presupuesto
B1: PRESUPUESTO ESTIMADO – ESCENARIO ALTO – PLAN DE COSTOS
B2: CuTuCo (Cultiva Tu Compra) – Marketplace SaaS B2B2C | Duoc UC Plaza Norte – Ingeniería en Informática
B3: Duración: 13 semanas (11/09/2026 – 10/12/2026) | Equipo: Vicente Rivera e Ignacio Fuenzalida | Moneda: pesos chilenos (CLP)
B4: Opción B: infraestructura productiva con redundancia, cumplimiento y revisión de seguridad externa. Mayor dedicación del equipo.
B5: SUPUESTOS (celdas azules con fondo amarillo = editables)
B6: Tipo de cambio (CLP por USD) | C6: 950 | D6: Supuesto del equipo; ajustar al valor del día de pago.
B7: Duración del proyecto (meses) | C7: 3 | D7: 13 semanas ≈ 3 meses.
B8: Semanas de trabajo | C8: 13 | D8: Acta de Constitución: semanas 1 a 13.
B9: Horas por semana por integrante | C9: 28 | D9: Dedicación estimada compatible con la carga académica.
B10: Contingencia sobre el subtotal | C10: 0.2 | D10: Reserva alta por integraciones reales (Webpay) y revisión externa.
B11: Valor de un notebook propio (CLP) | C11: 1000000 | D11: Estimación de mercado Chile.
B12: Vida útil del notebook (meses) | C12: 36 | D12: Depreciación lineal.
B13: Estado de cada monto: la leyenda completa está en la sección 10, al final de la hoja.
B14: 1. RECURSO HUMANO (valorizado a precio de mercado; no es desembolso)
B15: Rol | C15: Responsable | D15: Horas | E15: Valor hora (CLP) | F15: Costo (CLP) | G15: Observación | H15: Estado
B16: Jefe de Proyecto (JP) | C16: Vicente Rivera | D16: 65 | E16: 13388 | F16: =D16*E16 | G16: Costo empresa $2.142.000 / 160 h. Gestión, control y coordinación. | H16: Valorizado
B17: Arquitecto de Software (ASW) | C17: Vicente Rivera | D17: 65 | E17: 11156 | F17: =D17*E17 | G17: Costo empresa $1.785.000 / 160 h. Arquitectura y despliegue. | H17: Valorizado
B18: Administrador de BBDD (DBA) | C18: Vicente Rivera | D18: 60 | E18: 10041 | F18: =D18*E18 | G18: Costo empresa $1.606.500 / 160 h. PostgreSQL, RLS y scripts. | H18: Valorizado
B19: Programador Full Stack 1 – Backend (PFS 1) | C19: Vicente Rivera | D19: 160 | E19: 7438 | F19: =D19*E19 | G19: Costo empresa $1.190.000 / 160 h. FastAPI, pagos y correos. | H19: Valorizado
B20: Analista de Procesos (AP) | C20: Ignacio Fuenzalida | D20: 90 | E20: 5950 | F20: =D20*E20 | G20: Costo empresa $952.000 / 160 h. ERS, mockups y pruebas. | H20: Valorizado
B21: Programador Full Stack 2 – Frontend (PFS 2) | C21: Ignacio Fuenzalida | D21: 260 | E21: 9669 | F21: =D21*E21 | G21: Costo empresa $1.547.000 / 160 h. Vue.js + Vite. | H21: Valorizado
B22: Subtotal recurso humano | D22: =SUM(D16:D21) | F22: =SUM(F16:F21) | G22: Valor hora tomado de la tabla de roles del Acta (talent.com).
B23: Control de horas: Vicente Rivera | C23: Asignadas / disponibles | D23: =SUMIF($C$16:$C$21,"Vicente Rivera",$D$16:$D$21) | E23: =$C$8*$C$9 | F23: =IF(D23<=E23,"OK","Excede") | G23: Las horas asignadas no deben superar las disponibles.
B24: Control de horas: Ignacio Fuenzalida | C24: Asignadas / disponibles | D24: =SUMIF($C$16:$C$21,"Ignacio Fuenzalida",$D$16:$D$21) | E24: =$C$8*$C$9 | F24: =IF(D24<=E24,"OK","Excede") | G24: Las horas asignadas no deben superar las disponibles.
B26: 2. INFRAESTRUCTURA Y SERVICIOS – OPCIÓN B (PRODUCCIÓN CON REDUNDANCIA)
B27: Servicio | C27: Uso en CuTuCo | D27: Cantidad | E27: Valor unit. (USD) | F27: Costo (CLP) | G27: Observación | H27: Estado
B28: Dominio web (.cl / .com) | C28: Acceso público | D28: 1 | E28: 15 | F28: =D28*E28*$C$6 | G28: Cantidad en años. Estimación de mercado. | H28: Estimado
B29: Vercel Pro | C29: Frontend Vue.js + Vite | D29: 3 | E29: 20 | F29: =D29*E29*$C$6 | G29: Cantidad en meses. USD 20 por usuario al mes. | H29: Estimado
B30: Supabase Pro | C30: PostgreSQL, Auth, PostgREST, Storage | D30: 3 | E30: 25 | F30: =D30*E30*$C$6 | G30: Cantidad en meses. Incluye respaldos diarios. | H30: Estimado
B31: GCP Cloud Run (2 regiones) + Secret Manager | C31: FastAPI + Docker con redundancia | D31: 3 | E31: 40 | F31: =D31*E31*$C$6 | G31: Cantidad en meses. Cerca de 40% más que la Opción A (informe). | H31: Estimado
B32: Resend Pro | C32: Correos de Auth (SMTP) y de negocio (API) | D32: 3 | E32: 20 | F32: =D32*E32*$C$6 | G32: Cantidad en meses. Mayor volumen de correos. | H32: Estimado
B33: Transbank Webpay Mall (producción) | C33: Pagos reales | D33: 3 | E33: 0 | F33: =D33*E33*$C$6 | G33: Sin costo fijo; comisiones por transacción variables y no incluidas. | H33: Confirmado
B34: GitHub Team | C34: Repositorio y CI/CD (2 usuarios) | D34: 3 | E34: 8 | F34: =D34*E34*$C$6 | G34: Cantidad en meses. USD 4 por usuario al mes. | H34: Estimado
B35: Subtotal infraestructura (desembolso) | F35: =SUM(F28:F34) | G35: Costo mensual aproximado de USD 113, dentro del rango USD 100 a 120 del informe.
B37: 3. OTROS COSTOS DEL PROYECTO
B38: Concepto | C38: Detalle | D38: Cantidad | E38: Valor unit. (CLP) | F38: Costo (CLP) | G38: Observación | H38: Estado
B39: Internet y electricidad (trabajo remoto) | C39: Persona-mes | D39: =2*$C$7 | E39: 35000 | F39: =D39*E39 | G39: Supuesto: $35.000 mensuales por integrante. | H39: Estimado
B40: Depreciación de notebooks propios | C40: Equipo-mes | D40: =2*$C$7 | E40: =ROUND($C$11/$C$12,0) | F40: =D40*E40 | G40: Valor del equipo / vida útil. No se compran equipos nuevos. | H40: Estimado
B41: Impresión y material de la presentación final | C41: Global | D41: 1 | E41: 60000 | F41: =D41*E41 | G41: Supuesto del equipo. | H41: Estimado
B42: Herramientas de desarrollo y diseño | C42: Figma Professional (2 licencias) | D42: 6 | E42: 14250 | F42: =D42*E42 | G42: Cantidad en licencias-mes. USD 15 por licencia (a $950). | H42: Estimado
...

Sheet Medio Presupuesto
B1: PRESUPUESTO ESTIMADO – ESCENARIO MEDIO – PLAN DE COSTOS
B2: CuTuCo (Cultiva Tu Compra) – Marketplace SaaS B2B2C | Duoc UC Plaza Norte – Ingeniería en Informática
B3: Duración: 13 semanas (11/09/2026 – 10/12/2026) | Equipo: Vicente Rivera e Ignacio Fuenzalida | Moneda: pesos chilenos (CLP)
B4: Opción A reforzada: planes pagados en Supabase, Vercel y Cloud Run (sin depender de créditos), más horas de QA y asesoría legal básica.
B5: SUPUESTOS (celdas azules con fondo amarillo = editables)
B6: Tipo de cambio (CLP por USD) | C6: 950 | D6: Supuesto del equipo; ajustar al valor del día de pago.
B7: Duración del proyecto (meses) | C7: 3 | D7: 13 semanas ≈ 3 meses.
B8: Semanas de trabajo | C8: 13 | D8: Acta de Constitución: semanas 1 a 13.
B9: Horas por semana por integrante | C9: 24 | D9: Dedicación estimada compatible con la carga académica.
B10: Contingencia sobre el subtotal | C10: 0.15 | D10: Mayor reserva por servicios pagados y más horas de pruebas.
B11: Valor de un notebook propio (CLP) | C11: 800000 | D11: Estimación de mercado Chile.
B12: Vida útil del notebook (meses) | C12: 36 | D12: Depreciación lineal.
B13: Estado de cada monto: la leyenda completa está en la sección 10, al final de la hoja.
B14: 1. RECURSO HUMANO (valorizado a precio de mercado; no es desembolso)
B15: Rol | C15: Responsable | D15: Horas | E15: Valor hora (CLP) | F15: Costo (CLP) | G15: Observación | H15: Estado
B16: Jefe de Proyecto (JP) | C16: Vicente Rivera | D16: 55 | E16: 13388 | F16: =D16*E16 | G16: Costo empresa $2.142.000 / 160 h. Gestión, control y coordinación. | H16: Valorizado
B17: Arquitecto de Software (ASW) | C17: Vicente Rivera | D17: 55 | E17: 11156 | F17: =D17*E17 | G17: Costo empresa $1.785.000 / 160 h. Arquitectura y despliegue. | H17: Valorizado
B18: Administrador de BBDD (DBA) | C18: Vicente Rivera | D18: 55 | E18: 10041 | F18: =D18*E18 | G18: Costo empresa $1.606.500 / 160 h. PostgreSQL, RLS y scripts. | H18: Valorizado
B19: Programador Full Stack 1 – Backend (PFS 1) | C19: Vicente Rivera | D19: 135 | E19: 7438 | F19: =D19*E19 | G19: Costo empresa $1.190.000 / 160 h. FastAPI, pagos y correos. | H19: Valorizado
B20: Analista de Procesos (AP) | C20: Ignacio Fuenzalida | D20: 70 | E20: 5950 | F20: =D20*E20 | G20: Costo empresa $952.000 / 160 h. ERS, mockups y pruebas. | H20: Valorizado
B21: Programador Full Stack 2 – Frontend (PFS 2) | C21: Ignacio Fuenzalida | D21: 230 | E21: 9669 | F21: =D21*E21 | G21: Costo empresa $1.547.000 / 160 h. Vue.js + Vite. | H21: Valorizado
B22: Subtotal recurso humano | D22: =SUM(D16:D21) | F22: =SUM(F16:F21) | G22: Valor hora tomado de la tabla de roles del Acta (talent.com).
B23: Control de horas: Vicente Rivera | C23: Asignadas / disponibles | D23: =SUMIF($C$16:$C$21,"Vicente Rivera",$D$16:$D$21) | E23: =$C$8*$C$9 | F23: =IF(D23<=E23,"OK","Excede") | G23: Las horas asignadas no deben superar las disponibles.
B24: Control de horas: Ignacio Fuenzalida | C24: Asignadas / disponibles | D24: =SUMIF($C$16:$C$21,"Ignacio Fuenzalida",$D$16:$D$21) | E24: =$C$8*$C$9 | F24: =IF(D24<=E24,"OK","Excede") | G24: Las horas asignadas no deben superar las disponibles.
B26: 2. INFRAESTRUCTURA Y SERVICIOS – OPCIÓN A CON PLANES PAGADOS
B27: Servicio | C27: Uso en CuTuCo | D27: Cantidad | E27: Valor unit. (USD) | F27: Costo (CLP) | G27: Observación | H27: Estado
B28: Dominio web (.cl / .com) | C28: Acceso público | D28: 1 | E28: 15 | F28: =D28*E28*$C$6 | G28: Cantidad en años. Estimación de mercado. | H28: Estimado
B29: Vercel Pro | C29: Frontend Vue.js + Vite | D29: 3 | E29: 20 | F29: =D29*E29*$C$6 | G29: Cantidad en meses. USD 20 por usuario al mes (1 usuario). | H29: Estimado
B30: Supabase Pro | C30: PostgreSQL, Auth, PostgREST, Storage | D30: 3 | E30: 25 | F30: =D30*E30*$C$6 | G30: Cantidad en meses. Incluye respaldos diarios. | H30: Estimado
B31: GCP Cloud Run + Secret Manager | C31: FastAPI + Docker (us-central1) | D31: 3 | E31: 15 | F31: =D31*E31*$C$6 | G31: Cantidad en meses. Consumo estimado sin créditos GCP. | H31: Estimado
B32: Resend | C32: Correos de Auth (SMTP) y de negocio (API) | D32: 3 | E32: 0 | F32: =D32*E32*$C$6 | G32: Cantidad en meses. Nivel gratuito (hasta 3.000 correos/mes). | H32: Confirmado
B33: Transbank Webpay Mall Test | C33: Pagos en ambiente de integración | D33: 3 | E33: 0 | F33: =D33*E33*$C$6 | G33: Ambiente de pruebas sin costo. | H33: Confirmado
B34: GitHub + GitHub Actions | C34: Repositorio y CI/CD | D34: 3 | E34: 0 | F34: =D34*E34*$C$6 | G34: Cantidad en meses. Plan gratuito. | H34: Confirmado
B35: Subtotal infraestructura (desembolso) | F35: =SUM(F28:F34) | G35: Costo mensual aproximado de USD 60 más el dominio.
B37: 3. OTROS COSTOS DEL PROYECTO
B38: Concepto | C38: Detalle | D38: Cantidad | E38: Valor unit. (CLP) | F38: Costo (CLP) | G38: Observación | H38: Estado
B39: Internet y electricidad (trabajo remoto) | C39: Persona-mes | D39: =2*$C$7 | E39: 30000 | F39: =D39*E39 | G39: Supuesto: $30.000 mensuales por integrante. | H39: Estimado
B40: Depreciación de notebooks propios | C40: Equipo-mes | D40: =2*$C$7 | E40: =ROUND($C$11/$C$12,0) | F40: =D40*E40 | G40: Valor del equipo / vida útil. No se compran equipos nuevos. | H40: Estimado
B41: Impresión y material de la presentación final | C41: Global | D41: 1 | E41: 40000 | F41: =D41*E41 | G41: Supuesto del equipo. | H41: Estimado
B42: Herramientas de desarrollo y diseño | C42: Figma Professional (2 licencias) | D42: 6 | E42: 14250 | F42: =D42*E42 | G42: Cantidad en licencias-mes. USD 15 por licencia (a $950). | H42: Estimado
...

Sheet Bajo Presupuesto
B1: PRESUPUESTO ESTIMADO – ESCENARIO BAJO – PLAN DE COSTOS
B2: CuTuCo (Cultiva Tu Compra) – Marketplace SaaS B2B2C | Duoc UC Plaza Norte – Ingeniería en Informática
B3: Duración: 13 semanas (11/09/2026 – 10/12/2026) | Equipo: Vicente Rivera e Ignacio Fuenzalida | Moneda: pesos chilenos (CLP)
B4: Opción A: MVP académico con niveles gratuitos y créditos GCP. Equipo de dos personas, alcance de 22 requerimientos, sin gasto productivo.
B5: SUPUESTOS (celdas azules con fondo amarillo = editables)
B6: Tipo de cambio (CLP por USD) | C6: 950 | D6: Supuesto del equipo; ajustar al valor del día de pago.
B7: Duración del proyecto (meses) | C7: 3 | D7: 13 semanas ≈ 3 meses.
B8: Semanas de trabajo | C8: 13 | D8: Acta de Constitución: semanas 1 a 13.
B9: Horas por semana por integrante | C9: 20 | D9: Dedicación estimada compatible con la carga académica.
B10: Contingencia sobre el subtotal | C10: 0.1 | D10: Reserva básica; la infraestructura es casi gratuita.
B11: Valor de un notebook propio (CLP) | C11: 700000 | D11: Estimación de mercado Chile.
B12: Vida útil del notebook (meses) | C12: 36 | D12: Depreciación lineal.
B13: Estado de cada monto: la leyenda completa está en la sección 10, al final de la hoja.
B14: 1. RECURSO HUMANO (valorizado a precio de mercado; no es desembolso)
B15: Rol | C15: Responsable | D15: Horas | E15: Valor hora (CLP) | F15: Costo (CLP) | G15: Observación | H15: Estado
B16: Jefe de Proyecto (JP) | C16: Vicente Rivera | D16: 50 | E16: 13388 | F16: =D16*E16 | G16: Costo empresa $2.142.000 / 160 h. Gestión, control y coordinación. | H16: Valorizado
B17: Arquitecto de Software (ASW) | C17: Vicente Rivera | D17: 45 | E17: 11156 | F17: =D17*E17 | G17: Costo empresa $1.785.000 / 160 h. Arquitectura y despliegue. | H17: Valorizado
B18: Administrador de BBDD (DBA) | C18: Vicente Rivera | D18: 45 | E18: 10041 | F18: =D18*E18 | G18: Costo empresa $1.606.500 / 160 h. PostgreSQL, RLS y scripts. | H18: Valorizado
B19: Programador Full Stack 1 – Backend (PFS 1) | C19: Vicente Rivera | D19: 120 | E19: 7438 | F19: =D19*E19 | G19: Costo empresa $1.190.000 / 160 h. FastAPI, pagos y correos. | H19: Valorizado
B20: Analista de Procesos (AP) | C20: Ignacio Fuenzalida | D20: 60 | E20: 5950 | F20: =D20*E20 | G20: Costo empresa $952.000 / 160 h. ERS, mockups y pruebas. | H20: Valorizado
B21: Programador Full Stack 2 – Frontend (PFS 2) | C21: Ignacio Fuenzalida | D21: 200 | E21: 9669 | F21: =D21*E21 | G21: Costo empresa $1.547.000 / 160 h. Vue.js + Vite. | H21: Valorizado
B22: Subtotal recurso humano | D22: =SUM(D16:D21) | F22: =SUM(F16:F21) | G22: Valor hora tomado de la tabla de roles del Acta (talent.com).
B23: Control de horas: Vicente Rivera | C23: Asignadas / disponibles | D23: =SUMIF($C$16:$C$21,"Vicente Rivera",$D$16:$D$21) | E23: =$C$8*$C$9 | F23: =IF(D23<=E23,"OK","Excede") | G23: Las horas asignadas no deben superar las disponibles.
B24: Control de horas: Ignacio Fuenzalida | C24: Asignadas / disponibles | D24: =SUMIF($C$16:$C$21,"Ignacio Fuenzalida",$D$16:$D$21) | E24: =$C$8*$C$9 | F24: =IF(D24<=E24,"OK","Excede") | G24: Las horas asignadas no deben superar las disponibles.
B26: 2. INFRAESTRUCTURA Y SERVICIOS – OPCIÓN A (MVP ACADÉMICO)
B27: Servicio | C27: Uso en CuTuCo | D27: Cantidad | E27: Valor unit. (USD) | F27: Costo (CLP) | G27: Observación | H27: Estado
B28: Dominio web | C28: Acceso público | D28: 1 | E28: 12 | F28: =D28*E28*$C$6 | G28: Cantidad en años. Costo del informe: USD 12 al año. | H28: Estimado
B29: Vercel Hobby | C29: Frontend Vue.js + Vite | D29: 3 | E29: 0 | F29: =D29*E29*$C$6 | G29: Cantidad en meses. Nivel gratuito. | H29: Confirmado
B30: Supabase (nivel gratuito) | C30: PostgreSQL, Auth, PostgREST, Storage | D30: 3 | E30: 0 | F30: =D30*E30*$C$6 | G30: Cantidad en meses. Nivel gratuito. | H30: Confirmado
B31: GCP Cloud Run + Secret Manager | C31: FastAPI + Docker (us-central1) | D31: 3 | E31: 0 | F31: =D31*E31*$C$6 | G31: Cubierto por créditos GCP de USD 300 (vigentes hasta el 29/11). | H31: Confirmado
B32: Resend | C32: Correos de Auth (SMTP) y de negocio (API) | D32: 3 | E32: 0 | F32: =D32*E32*$C$6 | G32: Cantidad en meses. Nivel gratuito. | H32: Confirmado
B33: Transbank Webpay Mall Test | C33: Pagos en ambiente de integración | D33: 3 | E33: 0 | F33: =D33*E33*$C$6 | G33: Ambiente de pruebas sin costo. | H33: Confirmado
B34: GitHub + GitHub Actions | C34: Repositorio y CI/CD | D34: 3 | E34: 0 | F34: =D34*E34*$C$6 | G34: Cantidad en meses. Plan gratuito. | H34: Confirmado
B35: Subtotal infraestructura (desembolso) | F35: =SUM(F28:F34) | G35: Coincide con el orden de USD 12 indicado en el Acta.
B37: 3. OTROS COSTOS DEL PROYECTO
B38: Concepto | C38: Detalle | D38: Cantidad | E38: Valor unit. (CLP) | F38: Costo (CLP) | G38: Observación | H38: Estado
B39: Internet y electricidad (trabajo remoto) | C39: Persona-mes | D39: =2*$C$7 | E39: 25000 | F39: =D39*E39 | G39: Supuesto: $25.000 mensuales por integrante. | H39: Estimado
B40: Depreciación de notebooks propios | C40: Equipo-mes | D40: =2*$C$7 | E40: =ROUND($C$11/$C$12,0) | F40: =D40*E40 | G40: Valor del equipo / vida útil. No se compran equipos nuevos. | H40: Estimado
B41: Impresión y material de la presentación final | C41: Global | D41: 1 | E41: 30000 | F41: =D41*E41 | G41: Supuesto del equipo. | H41: Estimado
B42: Herramientas de desarrollo y diseño | C42: VS Code, DBeaver, Figma y GitHub Desktop (versiones gratuitas o académicas) | D42: 1 | E42: 0 | F42: =D42*E42 | G42: Versiones gratuitas o académicas. | H42: Estimado
...

Sheet Flujo de Caja y Viabilidad
B1: FLUJO DE CAJA PROYECTADO Y EVALUACIÓN DE VIABILIDAD – CU TUCO
B2: CuTuCo (Cultiva Tu Compra) – Marketplace SaaS B2B2C | Duoc UC Plaza Norte – Ingeniería en Informática
B3: Proyección a 5 años (Año 1 a Año 5) del negocio proyectado. Moneda: pesos chilenos (CLP) nominales.
B4: El MVP académico no factura: esta hoja modela la continuidad del negocio y no forma parte del presupuesto base de las hojas Alto, Medio y Bajo Presupuesto. Los supuestos editables están en amarillo y cada monto indica su estado (sección 6).
B5: La proyección NO incluye captación de clientes (marketing) ni costos variables por transacción: ambos están pendientes de cotización. Por eso el VAN y la TIR deben leerse como un techo referencial, no como un resultado esperado.
B6: 1. SUPUESTOS DEL MODELO (celdas azules con fondo amarillo = editables)
B7: Supuesto | C7: Valor | D7: Observación | H7: Estado
B8: Tipo de cambio (CLP por USD) | C8: ='Bajo Presupuesto'!C6 | D8: Tipo de cambio supuesto del presupuesto base (hoja Bajo Presupuesto, celda C6). | H8: Estimado
B9: Fee de intermediación sobre la venta | C9: 0.05 | D9: Fee base de 5% definido en el ERS (RF-005 y RF-014). Se evalúa en la sección 4. | H9: Confirmado
B10: Tarifa fija por pedido (CLP) | C10: 3500 | D10: Tarifa fija de delivery del ERS (RF-014), descontada en el Split Payment de Webpay Mall. | H10: Confirmado
B11: Ticket promedio por pedido (CLP) | C11: 12000 | D11: Supuesto del equipo: la documentación del proyecto no registra un ticket promedio. Pendiente de confirmación. | H11: Pendiente de confirmación
B12: Suscripción mensual por productor (CLP) | C12: 9900 | D12: Supuesto del equipo. La facturación de la suscripción no forma parte del MVP: se modela como negocio proyectado (Opción B). | H12: Pendiente de confirmación
B13: Adopción de la suscripción en el Año 1 | C13: 0.15 | D13: Supuesto del equipo; la adopción crece por año en la sección 2. | H13: Pendiente de confirmación
B14: Tasa de descuento anual para el VAN | C14: 0.15 | D14: El proyecto no define una tasa de descuento: es un supuesto explícito del equipo. Pendiente de confirmación. | H14: Pendiente de confirmación
B15: Costo de infraestructura productiva (USD por mes) | C15: 110 | D15: Punto medio del rango USD 100 a 120 documentado para la Opción B. | H15: Estimado
B16: Horas de operación y soporte al mes | C16: 40 | D16: Supuesto del equipo para sostener el sistema en producción. | H16: Pendiente de confirmación
B17: Valor hora de operación y soporte (CLP) | C17: ='Bajo Presupuesto'!$E$20 | D17: Valor hora del rol Analista de Procesos del presupuesto base (hoja Bajo Presupuesto, sección 1). | H17: Estimado
B18: Meses por año | C18: 12 | D18: Base de cálculo anual. | H18: Confirmado
B19: Incluir el trabajo valorizado del equipo en la inversión inicial (1 = sí, 0 = no) | C19: 1 | D19: Supuesto del equipo: para un negocio real, construir la plataforma cuesta el trabajo del proyecto. Con 1, la inversión inicial incluye el recurso humano valorizado de la hoja Bajo Presupuesto (celda F48). | H19: Pendiente de confirmación
B21: 2. PROYECCIÓN DE INGRESOS Y COSTOS (AÑO 1 A AÑO 5)
B22: Concepto | C22: Año 1 | D22: Año 2 | E22: Año 3 | F22: Año 4 | G22: Año 5 | H22: Observación
B23: Productores activos (supuesto) | C23: 15 | D23: 40 | E23: 80 | F23: 130 | G23: 200 | H23: Supuesto de penetración del equipo; pendiente de confirmación.
B24: Pedidos por productor al mes (supuesto) | C24: 4 | D24: 5 | E24: 6 | F24: 6 | G24: 7 | H24: Supuesto del equipo; pendiente de confirmación.
B25: Adopción de la suscripción (supuesto) | C25: 0.15 | D25: 0.25 | E25: 0.35 | F25: 0.4 | G25: 0.45 | H25: Supuesto del equipo; pendiente de confirmación.
B26: Pedidos al año | C26: =C23*C24*$C$18 | D26: =D23*D24*$C$18 | E26: =E23*E24*$C$18 | F26: =F23*F24*$C$18 | G26: =G23*G24*$C$18 | H26: Productores activos × pedidos por productor al mes × meses del año.
B27: Ticket promedio (CLP) | C27: =$C$11 | D27: =$C$11 | E27: =$C$11 | F27: =$C$11 | G27: =$C$11 | H27: Supuesto del modelo (celda C11).
B28: Venta total del marketplace (GMV) | C28: =C26*C27 | D28: =D26*D27 | E28: =E26*E27 | F28: =F26*F27 | G28: =G26*G27 | H28: Valor transado por los productores; no es ingreso de CuTuCo.
B29: INGRESOS DE CU TUCO
B30: Fee de intermediación (5% del GMV) | C30: =C28*$C$9 | D30: =D28*$C$9 | E30: =E28*$C$9 | F30: =F28*$C$9 | G30: =G28*$C$9 | H30: Ingreso por el fee base de 5% (RF-005 y RF-014).
B31: Tarifa fija por pedido ($3.500) | C31: =C26*$C$10 | D31: =D26*$C$10 | E31: =E26*$C$10 | F31: =F26*$C$10 | G31: =G26*$C$10 | H31: Se descuenta en el Split Payment de Webpay Mall (RF-014).
B32: Suscripción mensual de productores (fuera del MVP) | C32: =C23*C25*$C$12*$C$18 | D32: =D23*D25*$C$12*$C$18 | E32: =E23*E25*$C$12*$C$18 | F32: =F23*F25*$C$12*$C$18 | G32: =G23*G25*$C$12*$C$18 | H32: Facturación proyectada: no forma parte del MVP y no se cobra en el período académico.
B33: Total de ingresos | C33: =SUM(C30:C32) | D33: =SUM(D30:D32) | E33: =SUM(E30:E32) | F33: =SUM(F30:F32) | G33: =SUM(G30:G32) | H33: Suma de las tres líneas de ingreso.
B34: COSTOS RECURRENTES
B35: Infraestructura productiva | C35: =$C$15*$C$18*$C$8 | D35: =$C$15*$C$18*$C$8 | E35: =$C$15*$C$18*$C$8 | F35: =$C$15*$C$18*$C$8 | G35: =$C$15*$C$18*$C$8 | H35: USD 110 al mes según el supuesto; equivale al rango documentado de USD 100 a 120.
B36: Operación y soporte | C36: =$C$16*$C$17*$C$18 | D36: =$C$16*$C$17*$C$18 | E36: =$C$16*$C$17*$C$18 | F36: =$C$16*$C$17*$C$18 | G36: =$C$16*$C$17*$C$18 | H36: Horas al mes valorizadas al valor hora del supuesto.
B37: Captación de productores y compradores (marketing) | C37: 0 | D37: 0 | E37: 0 | F37: 0 | G37: 0 | H37: Pendiente de cotización: no se incorpora al flujo. Su ausencia explica por qué el VAN y la TIR son un techo referencial.
B38: Delivery asumido por CuTuCo | C38: 0 | D38: 0 | E38: 0 | F38: 0 | G38: 0 | H38: Escenario base: el despacho lo realiza el productor y no genera costo para CuTuCo. Alternativas evaluadas en la sección 8 de las hojas de presupuesto.
B39: Trámites y obligaciones por validar | C39: 0 | D39: 0 | E39: 0 | F39: 0 | G39: 0 | H39: Pendientes de cotización: no se incorporan al flujo hasta contar con el monto.
B40: Comisión de Transbank por transacción | C40: 0 | D40: 0 | E40: 0 | F40: 0 | G40: 0 | H40: Pendiente de confirmación: la comisión del contrato de Webpay Mall podría descontarse del ingreso por fee.
B41: Total de costos recurrentes | C41: =SUM(C35:C40) | D41: =SUM(D35:D40) | E41: =SUM(E35:E40) | F41: =SUM(F35:F40) | G41: =SUM(G35:G40) | H41: Costos que se repiten cada año.
...
